Workbook
Name BMI: 總表!#REF!
Name FFM_H: 總表!#REF!
Name FM_H: 總表!#REF!
Name 上次量測: 王律喆!$AE$2:$AE$1048576
Name 上次量測: 王婕菱!$AE$2:$AE$1048576
Name 上次量測: 王薇嘉!$AE$2:$AE$1048576
Name 上次量測: 江宜珊!$AE$2:$AE$1048576
Name 上次量測: 巫少輔!$AE$2:$AE$1048576
Name 上次量測: 李孟恩!$AE$2:$AE$1048576
Name 上次量測: 李祈恩!$AE$2:$AE$1048576
Name 上次量測: 林家嫙!$AE$2:$AE$1048576
Name 上次量測: 林唯均!$AE$2:$AE$1048576
Name 上次量測: 邱少萱!$AE$2:$AE$1048576
Name 上次量測: 邱義睿!$AE$2:$AE$1048576
Name 上次量測: 金怡君!$AE$2:$AE$1048576
Name 上次量測: 洪俊義!$AE$2:$AE$1048576
Name 上次量測: 范羽喬!$AE$2:$AE$1048576
Name 上次量測: 徐彧媐!$AE$2:$AE$1048576
Name 上次量測: 徐晧祐!$AE$2:$AE$1048576
Name 上次量測: 高心怡!$AE$2:$AE$1048576
Name 上次量測: 張芮恩!$AE$2:$AE$1048576
Name 上次量測: 郭依梵!$AE$2:$AE$1048576
Name 上次量測: 陳沛妤!$AE$2:$AE$1048576
Name 上次量測: 陳亮希!$AE$2:$AE$1048576
Name 上次量測: 陳鵬仁!$AE$2:$AE$1048576
Name 上次量測: 黃宇睿!$AE$2:$AE$1048576
Name 上次量測: 黃卓乘!$AE$2:$AE$1048576
Name 上次量測: 黃映瑄!$AE$2:$AE$1048576
Name 上次量測: 劉侑芸!$AE$2:$AE$1048576
Name 上次量測: 潘奎安!$AE$2:$AE$1048576
Name 上次量測: 潘奎恩!$AE$2:$AE$1048576
Name 上次量測: 蔡昇良!$AE$2:$AE$1048576
Name 上次量測: 蔣芷昀!$AE$2:$AE$1048576
Name 上次量測: 鄧鈺臻!$AE$2:$AE$1048576
Name 上次量測: 謝依玲!$AE$2:$AE$1048576
Name 上次量測: 謝宗佑!$AE$2:$AE$1048576
Name 上次量測: 羅嘉翎!$AE$2:$AE$1048576
Name 上次量測: 蘇柏亞!$AE$2:$AE$1048576
Name 上次量測: 黃鈺仁!$AE$2:$AE$1048576
Name 日期: 王律喆!$X$2:$X$1048576
Name 日期: 王婕菱!$X$2:$X$1048576
Name 日期: 王薇嘉!$X$2:$X$1048576
Name 日期: 江宜珊!$X$2:$X$1048576
Name 日期: 巫少輔!$X$2:$X$1048576
Name 日期: 李孟恩!$X$2:$X$1048576
Name 日期: 李祈恩!$X$2:$X$1048576
Name 日期: 林家嫙!$X$2:$X$1048576
Name 日期: 林唯均!$X$2:$X$1048576
Name 日期: 邱少萱!$X$2:$X$1048576
Name 日期: 邱義睿!$X$2:$X$1048576
Name 日期: 金怡君!$X$2:$X$1048576
Name 日期: 洪俊義!$X$2:$X$1048576
Name 日期: 范羽喬!$X$2:$X$1048576
Name 日期: 徐彧媐!$X$2:$X$1048576
Name 日期: 徐晧祐!$X$2:$X$1048576
Name 日期: 高心怡!$X$2:$X$1048576
Name 日期: 張芮恩!$X$2:$X$1048576
Name 日期: 郭依梵!$X$2:$X$1048576
Name 日期: 陳沛妤!$X$2:$X$1048576
Name 日期: 陳亮希!$X$2:$X$1048576

Sheet 比賽時間輸入
A1: 比賽種類 | B1: 比賽日期
A2: 45767 | B2: 亞洲主席盃 | D2: 現役
A3: 45768 | B3: 台南全中運 | D3: 退役
I27: 45396 | J27: 2024塞爾維亞公開賽
I28: 45435 | J28: 越南亞錦賽
A32: 45767 | B32: 亞洲主席盃

Sheet 資料輸入
E1: 姓名 | F1: 日期 | G1: 體重(kg) | H1: 體脂率(%) | I1: 脂肪重(kg) | J1: 去脂重(kg) | K1: 肌肉量 | L1: 身體總水份kg
E2: 黃鈺仁 | F2: 1140204 | G2: 88.9 | H2: 18.4 | I2: 16.4 | J2: 72.5 | K2: 68.8 | L2: 48.7 | N2: {=_xlfn.UNIQUE(E:E)} -> 姓名
E3: 蘇柏亞 | F3: 1120324 | G3: 55.3 | H3: 15.5 | I3: 8.6 | J3: 46.7 | K3: 43.8 | L3: 31.2 | N3: 黃鈺仁
E4: 蘇柏亞 | F4: 1120413 | G4: 55.8 | H4: 14.2 | I4: 7.9 | J4: 47.9 | K4: 44.9 | L4: 32 | N4: 蘇柏亞
E5: 蘇柏亞 | F5: 1120504 | G5: 54.2 | H5: 14.3 | I5: 7.8 | J5: 46.4 | K5: 43.5 | L5: 30.4 | N5: 羅嘉翎
E6: 蘇柏亞 | F6: 1120629 | G6: 54.4 | H6: 14.1 | I6: 7.7 | J6: 46.7 | K6: 43.8 | L6: 30.5 | N6: 邱義睿
E7: 蘇柏亞 | F7: 1120713 | G7: 56.1 | H7: 14.8 | I7: 8.3 | J7: 47.8 | K7: 44.8 | L7: 31.8 | N7: 李孟恩
E8: 蘇柏亞 | F8: 1120720 | G8: 55.6 | H8: 16 | I8: 8.9 | J8: 46.7 | K8: 43.8 | L8: 30.7 | N8: 徐晧祐
E9: 蘇柏亞 | F9: 1120817 | G9: 56.6 | H9: 17 | I9: 9.6 | J9: 47 | K9: 44.1 | L9: 31.3 | N9: 林唯均
E10: 蘇柏亞 | F10: 1120824 | G10: 56.8 | H10: 15.4 | I10: 8.7 | J10: 48.1 | K10: 45.1 | L10: 32.3 | N10: 陳鵬仁
E11: 蘇柏亞 | F11: 1120907 | G11: 56.6 | H11: 16.7 | I11: 9.5 | J11: 47.1 | K11: 44.1 | L11: 31.3 | N11: 陳亮希
E12: 蘇柏亞 | F12: 1121102 | G12: 55.5 | H12: 15.3 | I12: 8.5 | J12: 47 | K12: 44.1 | L12: 31.3 | N12: 洪俊義
E13: 蘇柏亞 | F13: 1121116 | G13: 55.1 | H13: 16 | I13: 8.8 | J13: 46.3 | K13: 43.4 | L13: 30.3 | N13: 潘奎恩
E14: 蘇柏亞 | F14: 1121123 | G14: 55.1 | H14: 16.2 | I14: 8.9 | J14: 46.2 | K14: 43.3 | L14: 30.5 | N14: 黃映瑄
... E41: 羅嘉翎 | F41: 1120717 | G41: 62 | H41: 20.9 | I41: 13 | J41: 49 | K41: 45.9 | L41: 31.8 | N41: 林〇瑋
E42: 羅嘉翎 | F42: 1120719 | G42: 61.1 | H42: 19.7 | I42: 12 | J42: 49.1 | K42: 46 | L42: 31.5 | N42: 0
E43: 羅嘉翎 | F43: 1120720 | G43: 60.3 | H43: 19.7 | I43: 11.9 | J43: 48.4 | K43: 45.3 | L43: 30.9
E44: 羅嘉翎 | F44: 1120724 | G44: 60.7 | H44: 18.8 | I44: 11.4 | J44: 49.3 | K44: 46.2 | L44: 31.6
E45: 羅嘉翎 | F45: 1120726 | G45: 60 | H45: 20.2 | I45: 12.1 | J45: 47.9 | K45: 44.9 | L45: 30.7
E46: 羅嘉翎 | F46: 1120811 | G46: 62.4 | H46: 21.7 | I46: 13.5 | J46: 48.9 | K46: 45.8 | L46: 31.9
E47: 羅嘉翎 | F47: 1120814 | G47: 61.8 | H47: 20.7 | I47: 12.8 | J47: 49 | K47: 45.9 | L47: 31.4
E48: 羅嘉翎 | F48: 1120817 | G48: 61.6 | H48: 20.1 | I48: 12.4 | J48: 49.2 | K48: 46.1 | L48: 31.3
E49: 羅嘉翎 | F49: 1120822 | G49: 60.6 | H49: 20 | I49: 12.1 | J49: 48.5 | K49: 45.4 | L49: 31.2
E50: 羅嘉翎 | F50: 1120911 | G50: 61.2 | H50: 19.2 | I50: 11.8 | J50: 49.4 | K50: 46.2 | L50: 31.9
E51: 羅嘉翎 | F51: 1120913 | G51: 60.1 | H51: 19.9 | I51: 12 | J51: 48.1 | K51: 45.1 | L51: 30.8
E52: 羅嘉翎 | F52: 1120915 | G52: 60.2 | H52: 20.2 | I52: 12.2 | J52: 48 | K52: 45 | L52: 30.7
E53: 羅嘉翎 | F53: 1120918 | G53: 59.5 | H53: 19.3 | I53: 11.5 | J53: 48 | K53: 45 | L53: 30.9
E54: 羅嘉翎 | F54: 1121020 | G54: 58.6 | H54: 19.6 | I54: 11.5 | J54: 47.1 | K54: 44.1 | L54: 29.8
... E364: 林〇瑋 | F364: 1140320 | G364: 64.8 | H364: 27.3 | I364: 17.7 | J364: 47.1 | K364: 44.1 | L364: 33.2

Sheet 總表
A1: 量測日期 | B1: 上次 量測 | C1: 姓名 | D1: 性別 | E1: 體重 | H1: 體脂率 | K1: 脂肪重 | N1: 去脂肪重 | Q1: 肌肉重 | T1: 總水份 | AC1: 減重建議
A2: "選取" | E2: 體重 | F2: 變化 | G2: 區間 | H2: 體脂率 | I2: 變化 | J2: 區間 | K2: 脂肪重 | L2: 變化 | M2: 區間 | N2: 去脂重 | O2: 變化 | P2: 區間 | Q2: 肌肉重 | R2: 變化 | S2: 區間 | T2: 總水份 | U2: 變化 | V2: 變化% | W2: 區間 | AA2: 量測日期 | AB2: 預計過磅時間 | AC2: 姓名 | AD2: 量級 | AE2: 賽事名稱/量級 | AF2: 目前體重 | AG2: 下周體重目標 | AH2: 差距 | AI2: 賽前過磅 | AJ2: 過磅倒數(週) | AK2: 建議減重 (未脫水狀態) | AL2: 脫水後體重 | AM2: 每週減重kg/周 | AN2: 賽前脫水3%(kg) | AO2: 剩餘體重脫水(體重%)
A3: =蘇柏亞!A3 -> 1140204 | B3: =蘇柏亞!B3 -> 33周前 | C3: =蘇柏亞!C3 -> 蘇柏亞 | D3: =蘇柏亞!D3 -> 女 | E3: =蘇柏亞!E3 -> 55.4 | F3: =蘇柏亞!F3 -> -1.1 | G3: =蘇柏亞!G3 -> Q2 | H3: =蘇柏亞!H3 -> 16.9 | ... W3: =蘇柏亞!W3 -> Q1 | AA3: =DATE(MID(A3,1,3)+1911,MID(A3,4,2),MID(A3,6,2)) -> 45692 | AB3: 45767 | AC3: =C3 -> 蘇柏亞 | AD3: 53 | AE3: =LOOKUP(AB3,比賽種類,比賽日期) -> 亞洲主席盃 | AF3: =E3 -> 55.4 | AG3: =AF3-AM3 -> 55.3244 | AH3: =AF3-AD3 -> 2.4 | AI3: =IF(AM3>0.8,"需注意","通過") -> 通過 | AJ3: =(AB3-AA3)/7 -> 10.714286 | AK3: =AL3-AD3 -> 0.81 | AL3: =AF3-AN3 -> 53.81 | AM3: =AK3/AJ3 -> 0.0756 | AN3: =AD3*0.03 -> 1.59 | AO3: =AH3/AF3 -> 0.0433213
A4: =羅嘉翎!A3 -> 1140102 | B4: =羅嘉翎!B3 -> 1周前 | C4: =羅嘉翎!C3 -> 羅嘉翎 | D4: =羅嘉翎!D3 -> 女 | E4: =羅嘉翎!E3 -> 62.2 | F4: =羅嘉翎!F3 -> -2.5 | G4: =羅嘉翎!G3 -> Q2 | H4: =羅嘉翎!H3 -> 21.2 | ... W4: =羅嘉翎!W3 -> Q2 | AA4: =DATE(MID(A4,1,3)+1911,MID(A4,4,2),MID(A4,6,2)) -> 45659 | AB4: 45767 | AC4: =C4 -> 羅嘉翎 | AD4: 62 | AE4: =LOOKUP(AB4,比賽種類,比賽日期) -> 亞洲主席盃 | AF4: =E4 -> 62.2 | AG4: =AF4-AM4 -> 62.307593 | AH4: =AF4-AD4 -> 0.2 | AI4: =IF(AM4>0.8,"需注意","通過") -> 通過 | AJ4: =(AB4-AA4)/7 -> 15.428571 | AK4: =AL4-AD4 -> -1.66 | AL4: =AF4-AN4 -> 60.34 | AM4: =AK4/AJ4 -> -0.10759259 | AN4: =AD4*0.03 -> 1.86 | AO4: =AH4/AF4 -> 0.0032154341
A5: =林唯均!A3 -> 1140307 | B5: =林唯均!B3 -> 4周前 | C5: =林唯均!C3 -> 林唯均 | D5: =林唯均!D3 -> 女 | E5: =林唯均!E3 -> 61.3 | F5: =林唯均!F3 -> -1.5 | G5: =林唯均!G3 -> Q3 | H5: =林唯均!H3 -> 21.7 | ... W5: =林唯均!W3 -> Q3 | AA5: =DATE(MID(A5,1,3)+1911,MID(A5,4,2),MID(A5,6,2)) -> 45723 | AB5: 45767 | AC5: =C5 -> 林唯均 | AD5: 57 | AE5: =LOOKUP(AB5,比賽種類,比賽日期) -> 亞洲主席盃 | AF5: =E5 -> 61.3 | AG5: =AF5-AM5 -> 60.887955 | AH5: =AF5-AD5 -> 4.3 | AI5: =IF(AM5>0.8,"需注意","通過") -> 通過 | AJ5: =(AB5-AA5)/7 -> 6.2857143 | AK5: =AL5-AD5 -> 2.59 | AL5: =AF5-AN5 -> 59.59 | AM5: =AK5/AJ5 -> 0.41204545 | AN5: =AD5*0.03 -> 1.71 | AO5: =AH5/AF5 -> 0.070146819
A6: =黃映瑄!A3 -> 1140307 | B6: =黃映瑄!B3 -> 4周前 | C6: =黃映瑄!C3 -> 黃映瑄 | D6: =黃映瑄!D3 -> 女 | E6: =黃映瑄!E3 -> 48 | F6: =黃映瑄!F3 -> -0.7 | G6: =黃映瑄!G3 -> Q1 | H6: =黃映瑄!H3 -> 13.6 | ... W6: =黃映瑄!W3 -> Q2 | AA6: =DATE(MID(A6,1,3)+1911,MID(A6,4,2),MID(A6,6,2)) -> 45723 | AB6: 45767 | AC6: =C6 -> 黃映瑄 | AD6: 46 | AE6: =LOOKUP(AB6,比賽種類,比賽日期) -> 亞洲主席盃 | AF6: =E6 -> 48 | AG6: =AF6-AM6 -> 47.901364 | AH6: =AF6-AD6 -> 2 | AI6: =IF(AM6>0.8,"需注意","通過") -> 通過 | AJ6: =(AB6-AA6)/7 -> 6.2857143 | AK6: =AL6-AD6 -> 0.62 | AL6: =AF6-AN6 -> 46.62 | AM6: =AK6/AJ6 -> 0.098636364 | AN6: =AD6*0.03 -> 1.38 | AO6: =AH6/AF6 -> 0.041666667
A7: =張芮恩!A3 -> 1140307 | B7: =張芮恩!B3 -> 4周前 | C7: =張芮恩!C3 -> 張芮恩 | D7: =張芮恩!D3 -> 女 | E7: =張芮恩!E3 -> 67 | F7: =張芮恩!F3 -> 0.8 | G7: =張芮恩!G3 -> Q4 | H7: =張芮恩!H3 -> 23.8 | ... W7: =張芮恩!W3 -> Q4 | AA7: =DATE(MID(A7,1,3)+1911,MID(A7,4,2),MID(A7,6,2)) -> 45723 | AB7: 45767 | AC7: =C7 -> 張芮恩 | AD7: 62 | AE7: =LOOKUP(AB7,比賽種類,比賽日期) -> 亞洲主席盃 | AF7: =E7 -> 67 | AG7: =AF7-AM7 -> 66.500455 | AH7: =AF7-AD7 -> 5 | AI7: =IF(AM7>0.8,"需注意","通過") -> 通過 | AJ7: =(AB7-AA7)/7 -> 6.2857143 | AK7: =AL7-AD7 -> 3.14 | AL7: =AF7-AN7 -> 65.14 | AM7: =AK7/AJ7 -> 0.49954545 | AN7: =AD7*0.03 -> 1.86 | AO7: =AH7/AF7 -> 0.074626866
A8: =邱少萱!A3 -> 1140320 | B8: =邱少萱!B3 -> 2周前 | C8: =邱少萱!C3 -> 邱少萱 | D8: =邱少萱!D3 -> 女 | E8: =邱少萱!E3 -> 59.6 | F8: =邱少萱!F3 -> 0.4 | G8: =邱少萱!G3 -> Q2 | H8: =邱少萱!H3 -> 18.1 | ... W8: =邱少萱!W3 -> Q3 | AA8: =DATE(MID(A8,1,3)+1911,MID(A8,4,2),MID(A8,6,2)) -> 45736 | AB8: 45767 | AC8: =C8 -> 邱少萱 | AD8: 67 | AE8: =LOOKUP(AB8,比賽種類,比賽日期) -> 亞洲主席盃 | AF8: =E8 -> 59.6 | AG8: =AF8-AM8 -> 61.724839 | AH8: =AF8-AD8 -> -7.4 | AI8: =IF(AM8>0.8,"需注意","通過") -> 通過 | AJ8: =(AB8-AA8)/7 -> 4.4285714 | AK8: =AL8-AD8 -> -9.41 | AL8: =AF8-AN8 -> 57.59 | AM8: =AK8/AJ8 -> -2.1248387 | AN8: =AD8*0.03 -> 2.01 | AO8: =AH8/AF8 -> -0.12416107
A9: =劉侑芸!A3 -> 1140307 | B9: =劉侑芸!B3 -> 4周前 | C9: =劉侑芸!C3 -> 劉侑芸 | D9: =劉侑芸!D3 -> 女 | E9: =劉侑芸!E3 -> 50.8 | F9: =劉侑芸!F3 -> 0.4 | G9: =劉侑芸!G3 -> Q4 | H9: =劉侑芸!H3 -> 11.7 | ... W9: =劉侑芸!W3 -> Q4 | AA9: =DATE(MID(A9,1,3)+1911,MID(A9,4,2),MID(A9,6,2)) -> 45723 | AB9: 45767 | AC9: =C9 -> 劉侑芸 | AD9: 49 | AE9: =LOOKUP(AB9,比賽種類,比賽日期) -> 亞洲主席盃 | AF9: =E9 -> 50.8 | AG9: =AF9-AM9 -> 50.7475 | AH9: =AF9-AD9 -> 1.8 | AI9: =IF(AM9>0.8,"需注意","通過") -> 通過 | AJ9: =(AB9-AA9)/7 -> 6.2857143 | AK9: =AL9-AD9 -> 0.33 | AL9: =AF9-AN9 -> 49.33 | AM9: =AK9/AJ9 -> 0.0525 | AN9: =AD9*0.03 -> 1.47 | AO9: =AH9/AF9 -> 0.035433071
A10: =江宜珊!A3 -> 1140307 | B10: =江宜珊!B3 -> 4周前 | C10: =江宜珊!C3 -> 江宜珊 | D10: =江宜珊!D3 -> 女 | E10: =江宜珊!E3 -> 55.7 | F10: =江宜珊!F3 -> 0.2 | G10: =江宜珊!G3 -> Q4 | H10: =江宜珊!H3 -> 25.6 | ... W10: =江宜珊!W3 -> Q4 | AA10: =DATE(MID(A10,1,3)+1911,MID(A10,4,2),MID(A10,6,2)) -> 45723 | AB10: 45767 | AC10: =C10 -> 江宜珊 | AD10: 53 | AE10: =LOOKUP(AB10,比賽種類,比賽日期) -> 亞洲主席盃 | AF10: =E10 -> 55.7 | AG10: =AF10-AM10 -> 55.523409 | AH10: =AF10-AD10 -> 2.7 | AI10: =IF(AM10>0.8,"需注意","通過") -> 通過 | AJ10: =(AB10-AA10)/7 -> 6.2857143 | AK10: =AL10-AD10 -> 1.11 | AL10: =AF10-AN10 -> 54.11 | AM10: =AK10/AJ10 -> 0.17659091 | AN10: =AD10*0.03 -> 1.59 | AO10: =AH10/AF10 -> 0.048473968
A11: =金怡君!A3 -> 1140320 | B11: =金怡君!B3 -> 2周前 | C11: =金怡君!C3 -> 金怡君 | D11: =金怡君!D3 -> 女 | E11: =金怡君!E3 -> 76.8 | F11: =金怡君!F3 -> -2.4 | G11: =金怡君!G3 -> Q1 | H11: =金怡君!H3 -> 37.2 | ... W11: =金怡君!W3 -> Q1 | AA11: =DATE(MID(A11,1,3)+1911,MID(A11,4,2),MID(A11,6,2)) -> 45736 | AB11: 45767 | AC11: =C11 -> 金怡君 | AD11: 73+ | AE11: =LOOKUP(AB11,比賽種類,比賽日期) -> 亞洲主席盃 | AF11: =E11 -> 76.8
A12: =范羽喬!A3 -> 1140307 | B12: =范羽喬!B3 -> 4周前 | C12: =范羽喬!C3 -> 范羽喬 | D12: =范羽喬!D3 -> 女 | E12: =范羽喬!E3 -> 48.6 | F12: =范羽喬!F3 -> -3.3 | G12: =范羽喬!G3 -> Q1 | H12: =范羽喬!H3 -> 21.8 | ... W12: =范羽喬!W3 -> Q1 | AA12: =DATE(MID(A12,1,3)+1911,MID(A12,4,2),MID(A12,6,2)) -> 45723 | AB12: 45767 | AC12: =C12 -> 范羽喬 | AD12: 46 | AE12: =LOOKUP(AB12,比賽種類,比賽日期) -> 亞洲主席盃 | AF12: =E12 -> 48.6 | AG12: =AF12-AM12 -> 48.405909 | AH12: =AF12-AD12 -> 2.6 | AI12: =IF(AM12>0.8,"需注意","通過") -> 通過 | AJ12: =(AB12-AA12)/7 -> 6.2857143 | AK12: =AL12-AD12 -> 1.22 | AL12: =AF12-AN12 -> 47.22 | AM12: =AK12/AJ12 -> 0.19409091 | AN12: =AD12*0.03 -> 1.38 | AO12: =AH12/AF12 -> 0.053497942
A13: =王薇嘉!A3 -> 1140307 | B13: =王薇嘉!B3 -> 4周前 | C13: =王薇嘉!C3 -> 王薇嘉 | D13: =王薇嘉!D3 -> 女 | E13: =王薇嘉!E3 -> 64.9 | F13: =王薇嘉!F3 -> 0 | G13: =王薇嘉!G3 -> Q4 | H13: =王薇嘉!H3 -> 25.7 | ... W13: =王薇嘉!W3 -> Q4 | AA13: =DATE(MID(A13,1,3)+1911,MID(A13,4,2),MID(A13,6,2)) -> 45723 | AB13: 45767 | AC13: =C13 -> 王薇嘉 | AD13: 67 | AE13: =LOOKUP(AB13,比賽種類,比賽日期) -> 亞洲主席盃 | AF13: =E13 -> 64.9 | AG13: =AF13-AM13 -> 65.553864 | AH13: =AF13-AD13 -> -2.1 | AI13: =IF(AM13>0.8,"需注意","通過") -> 通過 | AJ13: =(AB13-AA13)/7 -> 6.2857143 | AK13: =AL13-AD13 -> -4.11 | AL13: =AF13-AN13 -> 62.89 | AM13: =AK13/AJ13 -> -0.65386364 | AN13: =AD13*0.03 -> 2.01 | AO13: =AH13/AF13 -> -0.032357473
A14: =王婕菱!A3 -> 1140307 | B14: =王婕菱!B3 -> 4周前 | C14: =王婕菱!C3 -> 王婕菱 | D14: =王婕菱!D3 -> 女 | E14: =王婕菱!E3 -> 48.9 | F14: =王婕菱!F3 -> -1.3 | G14: =王婕菱!G3 -> Q1 | H14: =王婕菱!H3 -> 16.8 | ... W14: =王婕菱!W3 -> Q4 | AA14: =DATE(MID(A14,1,3)+1911,MID(A14,4,2),MID(A14,6,2)) -> 45723 | AB14: 45767 | AC14: =C14 -> 王婕菱 | AD14: 46 | AE14: =LOOKUP(AB14,比賽種類,比賽日期) -> 亞洲主席盃 | AF14: =E14 -> 48.9 | AG14: =AF14-AM14 -> 48.658182 | AH14: =AF14-AD14 -> 2.9 | AI14: =IF(AM14>0.8,"需注意","通過") -> 通過 | AJ14: =(AB14-AA14)/7 -> 6.2857143 | AK14: =AL14-AD14 -> 1.52 | AL14: =AF14-AN14 -> 47.52 | AM14: =AK14/AJ14 -> 0.24181818 | AN14: =AD14*0.03 -> 1.38 | AO14: =AH14/AF14 -> 0.059304703
A15: =林家嫙!A3 -> 1140307 | B15: =林家嫙!B3 -> 4周前 | C15: =林家嫙!C3 -> 林家嫙 | D15: =林家嫙!D3 -> 女 | E15: =林家嫙!E3 -> 62.1 | F15: =林家嫙!F3 -> -1.2 | G15: =林家嫙!G3 -> Q1 | H15: =林家嫙!H3 -> 23.9 | ... W15: =林家嫙!W3 -> Q1 | AA15: =DATE(MID(A15,1,3)+1911,MID(A15,4,2),MID(A15,6,2)) -> 45723 | AB15: 45767 | AC15: =C15 -> 林家嫙 | AD15: 67 | AE15: =LOOKUP(AB15,比賽種類,比賽日期) -> 亞洲主席盃 | AF15: =E15 -> 62.1 | AG15: =AF15-AM15 -> 63.199318 | AH15: =AF15-AD15 -> -4.9 | AI15: =IF(AM15>0.8,"需注意","通過") -> 通過 | AJ15: =(AB15-AA15)/7 -> 6.2857143 | AK15: =AL15-AD15 -> -6.91 | AL15: =AF15-AN15 -> 60.09 | AM15: =AK15/AJ15 -> -1.0993182 | AN15: =AD15*0.03 -> 2.01 | AO15: =AH15/AF15 -> -0.078904992
A16: =蔣芷昀!A3 -> 1140307 | B16: =蔣芷昀!B3 -> 4周前 | C16: =蔣芷昀!C3 -> 蔣芷昀 | D16: =蔣芷昀!D3 -> 女 | E16: =蔣芷昀!E3 -> 53.5 | F16: =蔣芷昀!F3 -> -2.2 | G16: =蔣芷昀!G3 -> Q1 | H16: =蔣芷昀!H3 -> 17.2 | ... W16: =蔣芷昀!W3 -> Q1 | AA16: =DATE(MID(A16,1,3)+1911,MID(A16,4,2),MID(A16,6,2)) -> 45723 | AB16: 45767 | AC16: =C16 -> 蔣芷昀 | AD16: 49 | AE16: =LOOKUP(AB16,比賽種類,比賽日期) -> 亞洲主席盃 | AF16: =E16 -> 53.5 | AG16: =AF16-AM16 -> 53.017955 | AH16: =AF16-AD16 -> 4.5 | AI16: =IF(AM16>0.8,"需注意","通過") -> 通過 | AJ16: =(AB16-AA16)/7 -> 6.2857143 | AK16: =AL16-AD16 -> 3.03 | AL16: =AF16-AN16 -> 52.03 | AM16: =AK16/AJ16 -> 0.48204545 | AN16: =AD16*0.03 -> 1.47 | AO16: =AH16/AF16 -> 0.08411215
A17: =郭依梵!A3 -> 1140307 | B17: =郭依梵!B3 -> 4周前 | C17: =郭依梵!C3 -> 郭依梵 | D17: =郭依梵!D3 -> 女 | E17: =郭依梵!E3 -> 55 | F17: =郭依梵!F3 -> -1.2 | G17: =郭依梵!G3 -> Q1 | H17: =郭依梵!H3 -> 14.9 | ... W17: =郭依梵!W3 -> Q1 | AA17: =DATE(MID(A17,1,3)+1911,MID(A17,4,2),MID(A17,6,2)) -> 45723 | AB17: 45767 | AC17: =C17 -> 郭依梵 | AD17: 53 | AE17: =LOOKUP(AB17,比賽種類,比賽日期) -> 亞洲主席盃 | AF17: =E17 -> 55 | AG17: =AF17-AM17 -> 54.934773 | AH17: =AF17-AD17 -> 2 | AI17: =IF(AM17>0.8,"需注意","通過") -> 通過 | AJ17: =(AB17-AA17)/7 -> 6.2857143 | AK17: =AL17-AD17 -> 0.41 | AL17: =AF17-AN17 -> 53.41 | AM17: =AK17/AJ17 -> 0.065227273 | AN17: =AD17*0.03 -> 1.59 | AO17: =AH17/AF17 -> 0.036363636
A18: =高心怡!A3 -> 1140307 | B18: =高心怡!B3 -> 4周前 | C18: =高心怡!C3 -> 高心怡 | D18: =高心怡!D3 -> 女 | E18: =高心怡!E3 -> 58.7 | F18: =高心怡!F3 -> -0.4 | G18: =高心怡!G3 -> Q1 | H18: =高心怡!H3 -> 20.6 | ... W18: =高心怡!W3 -> Q4 | AA18: =DATE(MID(A18,1,3)+1911,MID(A18,4,2),MID(A18,6,2)) -> 45723 | AB18: 45767 | AC18: =C18 -> 高心怡 | AD18: 57 | AE18: =LOOKUP(AB18,比賽種類,比賽日期) -> 亞洲主席盃 | AF18: =E18 -> 58.7 | AG18: =AF18-AM18 -> 58.701591 | AH18: =AF18-AD18 -> 1.7 | AI18: =IF(AM18>0.8,"需注意","通過") -> 通過 | AJ18: =(AB18-AA18)/7 -> 6.2857143 | AK18: =AL18-AD18 -> -0.01 | AL18: =AF18-AN18 -> 56.99 | AM18: =AK18/AJ18 -> -0.0015909091 | AN18: =AD18*0.03 -> 1.71 | AO18: =AH18/AF18 -> 0.028960818
A19: =謝依玲!A3 -> 1140307 | B19: =謝依玲!B3 -> 4周前 | C19: =謝依玲!C3 -> 謝依玲 | D19: =謝依玲!D3 -> 女 | E19: =謝依玲!E3 -> 63.7 | F19: =謝依玲!F3 -> -0.2 | G19: =謝依玲!G3 -> Q1 | H19: =謝依玲!H3 -> 25.6 | ... W19: =謝依玲!W3 -> Q4 | AA19: =DATE(MID(A19,1,3)+1911,MID(A19,4,2),MID(A19,6,2)) -> 45723 | AB19: 45767 | AC19: =C19 -> 謝依玲 | AD19: 62 | AE19: =LOOKUP(AB19,比賽種類,比賽日期) -> 亞洲主席盃 | AF19: =E19 -> 63.7 | AG19: =AF19-AM19 -> 63.725455 | AH19: =AF19-AD19 -> 1.7 | AI19: =IF(AM19>0.8,"需注意","通過") -> 通過 | AJ19: =(AB19-AA19)/7 -> 6.2857143 | AK19: =AL19-AD19 -> -0.16 | AL19: =AF19-AN19 -> 61.84 | AM19: =AK19/AJ19 -> -0.025454545 | AN19: =AD19*0.03 -> 1.86 | AO19: =AH19/AF19 -> 0.026687598
A20: =陳沛妤!A3 -> 1140307 | B20: =陳沛妤!B3 -> 4周前 | C20: =陳沛妤!C3 -> 陳沛妤 | D20: =陳沛妤!D3 -> 女 | E20: =陳沛妤!E3 -> 73.7 | F20: =陳沛妤!F3 -> -5 | G20: =陳沛妤!G3 -> Q1 | H20: =陳沛妤!H3 -> 31.3 | ... W20: =陳沛妤!W3 -> Q1 | AA20: =DATE(MID(A20,1,3)+1911,MID(A20,4,2),MID(A20,6,2)) -> 45723 | AB20: 45767 | AC20: =C20 -> 陳沛妤 | AD20: 73+ | AE20: =LOOKUP(AB20,比賽種類,比賽日期) -> 亞洲主席盃 | AF20: =E20 -> 73.7
A21: =鄧鈺臻!A3 -> 1140204 | B21: =鄧鈺臻!B3 -> #VALUE! | C21: =鄧鈺臻!C3 -> 鄧鈺臻 | D21: =鄧鈺臻!D3 -> 女 | E21: =鄧鈺臻!E3 -> 64.1 | F21: =鄧鈺臻!F3 -> 0 | G21: =鄧鈺臻!G3 -> Q4 | H21: =鄧鈺臻!H3 -> 30.1 | ... W21: =鄧鈺臻!W3 -> Q4 | AA21: =DATE(MID(A21,1,3)+1911,MID(A21,4,2),MID(A21,6,2)) -> 45692 | AB21: 45767 | AC21: =C21 -> 鄧鈺臻 | AD21: 73 | AE21: =LOOKUP(AB21,比賽種類,比賽日期) -> 亞洲主席盃 | AF21: =E21 -> 64.1 | AG21: =AF21-AM21 -> 65.135067 | AH21: =AF21-AD21 -> -8.9 | AI21: =IF(AM21>0.8,"需注意","通過") -> 通過 | AJ21: =(AB21-AA21)/7 -> 10.714286 | AK21: =AL21-AD21 -> -11.09 | AL21: =AF21-AN21 -> 61.91 | AM21: =AK21/AJ21 -> -1.0350667 | AN21: =AD21*0.03 -> 2.19 | AO21: =AH21/AF21 -> -0.13884555
A22: =徐彧媐!A3 -> 1140204 | B22: =徐彧媐!B3 -> #VALUE! | C22: =徐彧媐!C3 -> 徐彧媐 | D22: =徐彧媐!D3 -> 女 | E22: =徐彧媐!E3 -> 71.3 | F22: =徐彧媐!F3 -> 0 | G22: =徐彧媐!G3 -> Q4 | H22: =徐彧媐!H3 -> 33.8 | ... W22: =徐彧媐!W3 -> Q4 | AA22: =DATE(MID(A22,1,3)+1911,MID(A22,4,2),MID(A22,6,2)) -> 45692 | AB22: 45767 | AC22: =C22 -> 徐彧媐 | AD22: 73 | AE22: =LOOKUP(AB22,比賽種類,比賽日期) -> 亞洲主席盃 | AF22: =E22 -> 71.3 | AG22: =AF22-AM22 -> 71.663067 | AH22: =AF22-AD22 -> -1.7 | AI22: =IF(AM22>0.8,"需注意","通過") -> 通過 | AJ22: =(AB22-AA22)/7 -> 10.714286 | AK22: =AL22-AD22 -> -3.89 | AL22: =AF22-AN22 -> 69.11 | AM22: =AK22/AJ22 -> -0.36306667 | AN22: =AD22*0.03 -> 2.19 | AO22: =AH22/AF22 -> -0.023842917
A23: =黃鈺仁!A3 -> 1140320 | B23: =黃鈺仁!B3 -> 2周前 | C23: =黃鈺仁!C3 -> 黃鈺仁 | D23: =黃鈺仁!D3 -> 男 | E23: =黃鈺仁!E3 -> 87.2 | F23: =黃鈺仁!F3 -> -0.3 | G23: =黃鈺仁!G3 -> Q1 | H23: =黃鈺仁!H3 -> 17.9 | ... W23: =黃鈺仁!W3 -> Q1 | AA23: =DATE(MID(A23,1,3)+1911,MID(A23,4,2),MID(A23,6,2)) -> 45736 | AB23: 45767 | AC23: =C23 -> 黃鈺仁 | AD23: 80+ | AE23: =LOOKUP(AB23,比賽種類,比賽日期) -> 亞洲主席盃 | AF23: =E23 -> 87.2
A24: =邱義睿!A3 -> 1140307 | B24: =邱義睿!B3 -> 4周前 | C24: =邱義睿!C3 -> 邱義睿 | D24: =邱義睿!D3 -> 男 | E24: =邱義睿!E3 -> 74.1 | F24: =邱義睿!F3 -> -1.7 | G24: =邱義睿!G3 -> Q3 | H24: =邱義睿!H3 -> 9.4 | ... W24: =邱義睿!W3 -> Q4 | AA24: =DATE(MID(A24,1,3)+1911,MID(A24,4,2),MID(A24,6,2)) -> 45723 | AB24: 45767 | AC24: =C24 -> 邱義睿 | AD24: 68 | AE24: =LOOKUP(AB24,比賽種類,比賽日期) -> 亞洲主席盃 | AF24: =E24 -> 74.1 | AG24: =AF24-AM24 -> 73.454091 | AH24: =AF24-AD24 -> 6.1 | AI24: =IF(AM24>0.8,"需注意","通過") -> 通過 | AJ24: =(AB24-AA24)/7 -> 6.2857143 | AK24: =AL24-AD24 -> 4.06 | AL24: =AF24-AN24 -> 72.06 | AM24: =AK24/AJ24 -> 0.64590909 | AN24: =AD24*0.03 -> 2.04 | AO24: =AH24/AF24 -> 0.082321188
A25: =李孟恩!A3 -> 1140204 | B25: =李孟恩!B3 -> 31周前 | C25: =李孟恩!C3 -> 李孟恩 | D25: =李孟恩!D3 -> 男 | E25: =李孟恩!E3 -> 99.4 | F25: =李孟恩!F3 -> 3.2 | G25: =李孟恩!G3 -> Q4 | H25: =李孟恩!H3 -> 19.3 | ... W25: =李孟恩!W3 -> Q1 | AA25: =DATE(MID(A25,1,3)+1911,MID(A25,4,2),MID(A25,6,2)) -> 45692 | AB25: 45767 | AC25: =C25 -> 李孟恩 | AD25: 80+ | AE25: =LOOKUP(AB25,比賽種類,比賽日期) -> 亞洲主席盃 | AF25: =E25 -> 99.4
A26: =徐晧祐!A3 -> 1140307 | B26: =徐晧祐!B3 -> 4周前 | C26: =徐晧祐!C3 -> 徐晧祐 | D26: =徐晧祐!D3 -> 男 | E26: =徐晧祐!E3 -> 70.4 | F26: =徐晧祐!F3 -> -0.2 | G26: =徐晧祐!G3 -> Q2 | H26: =徐晧祐!H3 -> 6.8 | ... W26: =徐晧祐!W3 -> Q4 | AA26: =DATE(MID(A26,1,3)+1911,MID(A26,4,2),MID(A26,6,2)) -> 45723 | AB26: 45767 | AC26: =C26 -> 徐晧祐 | AD26: 68 | AE26: =LOOKUP(AB26,比賽種類,比賽日期) -> 亞洲主席盃 | AF26: =E26 -> 70.4 | AG26: =AF26-AM26 -> 70.342727 | AH26: =AF26-AD26 -> 2.4 | AI26: =IF(AM26>0.8,"需注意","通過") -> 通過 | AJ26: =(AB26-AA26)/7 -> 6.2857143 | AK26: =AL26-AD26 -> 0.36 | AL26: =AF26-AN26 -> 68.36 | AM26: =AK26/AJ26 -> 0.057272727 | AN26: =AD26*0.03 -> 2.04 | AO26: =AH26/AF26 -> 0.034090909
A27: =陳鵬仁!A3 -> 1140307 | B27: =陳鵬仁!B3 -> 4周前 | C27: =陳鵬仁!C3 -> 陳鵬仁 | D27: =陳鵬仁!D3 -> 男 | E27: =陳鵬仁!E3 -> 63.4 | F27: =陳鵬仁!F3 -> -2.2 | G27: =陳鵬仁!G3 -> Q1 | H27: =陳鵬仁!H3 -> 8.5 | ... W27: =陳鵬仁!W3 -> Q1 | AA27: =DATE(MID(A27,1,3)+1911,MID(A27,4,2),MID(A27,6,2)) -> 45723 | AB27: 45767 | AC27: =C27 -> 陳鵬仁 | AD27: 63 | AE27: =LOOKUP(AB27,比賽種類,比賽日期) -> 亞洲主席盃 | AF27: =E27 -> 63.4 | AG27: =AF27-AM27 -> 63.637045 | AH27: =AF27-AD27 -> 0.4 | AI27: =IF(AM27>0.8,"需注意","通過") -> 通過 | AJ27: =(AB27-AA27)/7 -> 6.2857143 | AK27: =AL27-AD27 -> -1.49 | AL27: =AF27-AN27 -> 61.51 | AM27: =AK27/AJ27 -> -0.23704545 | AN27: =AD27*0.03 -> 1.89 | AO27: =AH27/AF27 -> 0.0063091483
A28: =陳亮希!A3 -> 1140307 | B28: =陳亮希!B3 -> 4周前 | C28: =陳亮希!C3 -> 陳亮希 | D28: =陳亮希!D3 -> 男 | E28: =陳亮希!E3 -> 90.9 | F28: =陳亮希!F3 -> -0.4 | G28: =陳亮希!G3 -> Q1 | H28: =陳亮希!H3 -> 16.9 | ... W28: =陳亮希!W3 -> Q4 | AA28: =DATE(MID(A28,1,3)+1911,MID(A28,4,2),MID(A28,6,2)) -> 45723 | AB28: 45767 | AC28: =C28 -> 陳亮希 | AD28: 87 | AE28: =LOOKUP(AB28,比賽種類,比賽日期) -> 亞洲主席盃 | AF28: =E28 -> 90.9 | AG28: =AF28-AM28 -> 90.694773 | AH28: =AF28-AD28 -> 3.9 | AI28: =IF(AM28>0.8,"需注意","通過") -> 通過 | AJ28: =(AB28-AA28)/7 -> 6.2857143 | AK28: =AL28-AD28 -> 1.29 | AL28: =AF28-AN28 -> 88.29 | AM28: =AK28/AJ28 -> 0.20522727 | AN28: =AD28*0.03 -> 2.61 | AO28: =AH28/AF28 -> 0.04290429
A29: =洪俊義!A3 -> 1140320 | B29: =洪俊義!B3 -> 2周前 | C29: =洪俊義!C3 -> 洪俊義 | D29: =洪俊義!D3 -> 男 | E29: =洪俊義!E3 -> 80.7 | F29: =洪俊義!F3 -> 0.2 | G29: =洪俊義!G3 -> Q2 | H29: =洪俊義!H3 -> 10.2 | ... W29: =洪俊義!W3 -> Q2 | AA29: =DATE(MID(A29,1,3)+1911,MID(A29,4,2),MID(A29,6,2)) -> 45736 | AB29: 45767 | AC29: =C29 -> 洪俊義 | AD29: 80 | AE29: =LOOKUP(AB29,比賽種類,比賽日期) -> 亞洲主席盃 | AF29: =E29 -> 80.7 | AG29: =AF29-AM29 -> 81.083871 | AH29: =AF29-AD29 -> 0.7 | AI29: =IF(AM29>0.8,"需注意","通過") -> 通過 | AJ29: =(AB29-AA29)/7 -> 4.4285714 | AK29: =AL29-AD29 -> -1.7 | AL29: =AF29-AN29 -> 78.3 | AM29: =AK29/AJ29 -> -0.38387097 | AN29: =AD29*0.03 -> 2.4 | AO29: =AH29/AF29 -> 0.0086741016
A30: =潘奎恩!A3 -> 1140307 | B30: =潘奎恩!B3 -> 4周前 | C30: =潘奎恩!C3 -> 潘奎恩 | D30: =潘奎恩!D3 -> 男 | E30: =潘奎恩!E3 -> 74.2 | F30: =潘奎恩!F3 -> -0.2 | G30: =潘奎恩!G3 -> Q1 | H30: =潘奎恩!H3 -> 11.2 | ... W30: =潘奎恩!W3 -> Q4 | AA30: =DATE(MID(A30,1,3)+1911,MID(A30,4,2),MID(A30,6,2)) -> 45723 | AB30: 45767 | AC30: =C30 -> 潘奎恩 | AD30: 74 | AE30: =LOOKUP(AB30,比賽種類,比賽日期) -> 亞洲主席盃 | AF30: =E30 -> 74.2 | AG30: =AF30-AM30 -> 74.521364 | AH30: =AF30-AD30 -> 0.2 | AI30: =IF(AM30>0.8,"需注意","通過") -> 通過 | AJ30: =(AB30-AA30)/7 -> 6.2857143 | AK30: =AL30-AD30 -> -2.02 | AL30: =AF30-AN30 -> 71.98 | AM30: =AK30/AJ30 -> -0.32136364 | AN30: =AD30*0.03 -> 2.22 | AO30: =AH30/AF30 -> 0.0026954178
A31: =蔡昇良!A3 -> 1130530 | B31: =蔡昇良!B3 -> 5周前 | C31: =蔡昇良!C3 -> 蔡昇良 | D31: =蔡昇良!D3 -> 男 | E31: =蔡昇良!E3 -> 73.6 | F31: =蔡昇良!F3 -> 0.3 | G31: =蔡昇良!G3 -> Q1 | H31: =蔡昇良!H3 -> 8.2 | ... W31: =蔡昇良!W3 -> Q1 | AA31: =DATE(MID(A31,1,3)+1911,MID(A31,4,2),MID(A31,6,2)) -> 45442 | AB31: 45767 | AC31: =C31 -> 蔡昇良 | AE31: =LOOKUP(AB31,比賽種類,比賽日期) -> 亞洲主席盃 | AF31: =E31 -> 73.6 | AG31: =AF31-AM31 -> 72.014769 | AH31: =AF31-AD31 -> 73.6 | AI31: =IF(AM31>0.8,"需注意","通過") -> 需注意 | AJ31: =(AB31-AA31)/7 -> 46.428571 | AK31: =AL31-AD31 -> 73.6 | AL31: =AF31-AN31 -> 73.6 | AM31: =AK31/AJ31 -> 1.5852308 | AN31: =AD31*0.03 -> 0 | AO31: =AH31/AF31 -> 1
A32: =謝宗佑!A3 -> 1140307 | B32: =謝宗佑!B3 -> 4周前 | C32: =謝宗佑!C3 -> 謝宗佑 | D32: =謝宗佑!D3 -> 男 | E32: =謝宗佑!E3 -> 76.8 | F32: =謝宗佑!F3 -> -0.8 | G32: =謝宗佑!G3 -> Q3 | H32: =謝宗佑!H3 -> 17.3 | ... W32: =謝宗佑!W3 -> Q1 | AA32: =DATE(MID(A32,1,3)+1911,MID(A32,4,2),MID(A32,6,2)) -> 45723 | AB32: 45767 | AC32: =C32 -> 謝宗佑 | AD32: 74 | AE32: =LOOKUP(AB32,比賽種類,比賽日期) -> 亞洲主席盃 | AF32: =E32 -> 76.8 | AG32: =AF32-AM32 -> 76.707727 | AH32: =AF32-AD32 -> 2.8 | AI32: =IF(AM32>0.8,"需注意","通過") -> 通過 | AJ32: =(AB32-AA32)/7 -> 6.2857143 | AK32: =AL32-AD32 -> 0.58 | AL32: =AF32-AN32 -> 74.58 | AM32: =AK32/AJ32 -> 0.092272727 | AN32: =AD32*0.03 -> 2.22 | AO32: =AH32/AF32 -> 0.036458333
A33: =黃卓乘!A3 -> 1140307 | B33: =黃卓乘!B3 -> 4周前 | C33: =黃卓乘!C3 -> 黃卓乘 | D33: =黃卓乘!D3 -> 男 | E33: =黃卓乘!E3 -> 65.1 | F33: =黃卓乘!F3 -> -0.1 | G33: =黃卓乘!G3 -> Q1 | H33: =黃卓乘!H3 -> 12.1 | ... W33: =黃卓乘!W3 -> Q1 | AA33: =DATE(MID(A33,1,3)+1911,MID(A33,4,2),MID(A33,6,2)) -> 45723 | AB33: 45767 | AC33: =C33 -> 黃卓乘 | AD33: 63 | AE33: =LOOKUP(AB33,比賽種類,比賽日期) -> 亞洲主席盃 | AF33: =E33 -> 65.1 | AG33: =AF33-AM33 -> 65.066591 | AH33: =AF33-AD33 -> 2.1 | AI33: =IF(AM33>0.8,"需注意","通過") -> 通過 | AJ33: =(AB33-AA33)/7 -> 6.2857143 | AK33: =AL33-AD33 -> 0.21 | AL33: =AF33-AN33 -> 63.21 | AM33: =AK33/AJ33 -> 0.033409091 | AN33: =AD33*0.03 -> 1.89 | AO33: =AH33/AF33 -> 0.032258065
A34: =巫少輔!A3 -> 1140307 | B34: =巫少輔!B3 -> 4周前 | C34: =巫少輔!C3 -> 巫少輔 | D34: =巫少輔!D3 -> 男 | E34: =巫少輔!E3 -> 79.8 | F34: =巫少輔!F3 -> 2.5 | G34: =巫少輔!G3 -> Q4 | H34: =巫少輔!H3 -> 13.9 | ... W34: =巫少輔!W3 -> Q4 | AA34: =DATE(MID(A34,1,3)+1911,MID(A34,4,2),MID(A34,6,2)) -> 45723 | AB34: 45767 | AC34: =C34 -> 巫少輔 | AD34: 80 | AE34: =LOOKUP(AB34,比賽種類,比賽日期) -> 亞洲主席盃 | AF34: =E34 -> 79.8 | AG34: =AF34-AM34 -> 80.213636 | AH34: =AF34-AD34 -> -0.2 | AI34: =IF(AM34>0.8,"需注意","通過") -> 通過 | AJ34: =(AB34-AA34)/7 -> 6.2857143 | AK34: =AL34-AD34 -> -2.6 | AL34: =AF34-AN34 -> 77.4 | AM34: =AK34/AJ34 -> -0.41363636 | AN34: =AD34*0.03 -> 2.4 | AO34: =AH34/AF34 -> -0.0025062657
A35: =李祈恩!A3 -> 1140320 | B35: =李祈恩!B3 -> 2周前 | C35: =李祈恩!C3 -> 李祈恩 | D35: =李祈恩!D3 -> 男 | E35: =李祈恩!E3 -> 57.7 | F35: =李祈恩!F3 -> 0 | G35: =李祈恩!G3 -> Q1 | H35: =李祈恩!H3 -> 9.3 | ... W35: =李祈恩!W3 -> Q4 | AA35: =DATE(MID(A35,1,3)+1911,MID(A35,4,2),MID(A35,6,2)) -> 45736 | AB35: 45767 | AC35: =C35 -> 李祈恩 | AD35: 54 | AE35: =LOOKUP(AB35,比賽種類,比賽日期) -> 亞洲主席盃 | AF35: =E35 -> 57.7 | AG35: =AF35-AM35 -> 57.230323 | AH35: =AF35-AD35 -> 3.7 | AI35: =IF(AM35>0.8,"需注意","通過") -> 通過 | AJ35: =(AB35-AA35)/7 -> 4.4285714 | AK35: =AL35-AD35 -> 2.08 | AL35: =AF35-AN35 -> 56.08 | AM35: =AK35/AJ35 -> 0.46967742 | AN35: =AD35*0.03 -> 1.62 | AO35: =AH35/AF35 -> 0.064124783
A36: =潘奎安!A3 -> 1140307 | B36: =潘奎安!B3 -> 4周前 | C36: =潘奎安!C3 -> 潘奎安 | D36: =潘奎安!D3 -> 男 | E36: =潘奎安!E3 -> 63.2 | F36: =潘奎安!F3 -> -0.7 | G36: =潘奎安!G3 -> Q1 | H36: =潘奎安!H3 -> 4.6 | ... W36: =潘奎安!W3 -> Q4 | AA36: =DATE(MID(A36,1,3)+1911,MID(A36,4,2),MID(A36,6,2)) -> 45723 | AB36: 45767 | AC36: =C36 -> 潘奎安 | AD36: 58 | AE36: =LOOKUP(AB36,比賽種類,比賽日期) -> 亞洲主席盃 | AF36: =E36 -> 63.2 | AG36: =AF36-AM36 -> 62.649545 | AH36: =AF36-AD36 -> 5.2 | AI36: =IF(AM36>0.8,"需注意","通過") -> 通過 | AJ36: =(AB36-AA36)/7 -> 6.2857143 | AK36: =AL36-AD36 -> 3.46 | AL36: =AF36-AN36 -> 61.46 | AM36: =AK36/AJ36 -> 0.55045455 | AN36: =AD36*0.03 -> 1.74 | AO36: =AH36/AF36 -> 0.082278481
A37: =王律喆!A3 -> 1140307 | B37: =王律喆!B3 -> 4周前 | C37: =王律喆!C3 -> 王律喆 | D37: =王律喆!D3 -> 男 | E37: =王律喆!E3 -> 59.2 | F37: =王律喆!F3 -> -0.7 | G37: =王律喆!G3 -> Q1 | H37: =王律喆!H3 -> 10.1 | ... W37: =王律喆!W3 -> Q4 | AA37: =DATE(MID(A37,1,3)+1911,MID(A37,4,2),MID(A37,6,2)) -> 45723 | AB37: 45767 | AC37: =C37 -> 王律喆 | AD37: 58 | AE37: =LOOKUP(AB37,比賽種類,比賽日期) -> 亞洲主席盃 | AF37: =E37 -> 59.2 | AG37: =AF37-AM37 -> 59.285909 | AH37: =AF37-AD37 -> 1.2 | AI37: =IF(AM37>0.8,"需注意","通過") -> 通過 | AJ37: =(AB37-AA37)/7 -> 6.2857143 | AK37: =AL37-AD37 -> -0.54 | AL37: =AF37-AN37 -> 57.46 | AM37: =AK37/AJ37 -> -0.085909091 | AN37: =AD37*0.03 -> 1.74 | AO37: =AH37/AF37 -> 0.02027027
A38: =黃宇睿!A3 -> 1140307 | B38: =黃宇睿!B3 -> 4周前 | C38: =黃宇睿!C3 -> 黃宇睿 | D38: =黃宇睿!D3 -> 男 | E38: =黃宇睿!E3 -> 72.5 | F38: =黃宇睿!F3 -> -1.9 | G38: =黃宇睿!G3 -> Q1 | H38: =黃宇睿!H3 -> 9 | ... W38: =黃宇睿!W3 -> Q1 | AA38: =DATE(MID(A38,1,3)+1911,MID(A38,4,2),MID(A38,6,2)) -> 45723 | AB38: 45767 | AC38: =C38 -> 黃宇睿 | AD38: 68 | AE38: =LOOKUP(AB38,比賽種類,比賽日期) -> 亞洲主席盃 | AF38: =E38 -> 72.5 | AG38: =AF38-AM38 -> 72.108636 | AH38: =AF38-AD38 -> 4.5 | AI38: =IF(AM38>0.8,"需注意","通過") -> 通過 | AJ38: =(AB38-AA38)/7 -> 6.2857143 | AK38: =AL38-AD38 -> 2.46 | AL38: =AF38-AN38 -> 70.46 | AM38: =AK38/AJ38 -> 0.39136364 | AN38: =AD38*0.03 -> 2.04 | AO38: =AH38/AF38 -> 0.062068966

Sheet 蘇柏亞
A1: 量測日期 | B1: 上次量測 | C1: 姓名 | D1: 性別 | E1: 體重 | H1: 體脂率 | K1: 脂肪重 | N1: 去脂肪重 | Q1: 肌肉重 | T1: 總水份 | X1: 日期 | Y1: 體重(kg) | Z1: 體脂率(%) | AA1: 脂肪重(kg) | AB1: 去脂重(kg) | AC1: 肌肉量 | AD1: 身體總水份kg | AE1: 上次量測 | AF1: 星期 | AG1: 身體總水份% | AH1: 體重變化 | AI1: 體脂率變化 | AJ1: 脂肪重變化 | AK1: 去脂重變化 | AL1: 肌肉量變化 | AM1: 水分變化KG | AN1: 水分變化%
A2: "選取" | E2: 體重 | F2: 變化 | G2: 區間 | H2: 體脂率 | I2: 變化 | J2: 區間 | K2: 脂肪重 | L2: 變化 | M2: 區間 | N2: 去脂重 | O2: 變化 | P2: 區間 | Q2: 肌肉重 | R2: 變化 | S2: 區間 | T2: 總水份 | U2: 變化 | V2: 變化% | W2: 區間 | X2: {=_xlfn._xlws.SORT(_xlfn._xlws.FILTER(資料輸入!F:L, ISNUMBER(MATCH(資料輸入!E:E, 蘇柏亞!C3, 0))), 1, TRUE)} -> 1120324 | Y2: 55.3 | Z2: 15.5 | AA2: 8.6 | AB2: 46.7 | AC2: 43.8 | AD2: 31.2 | AF2: =DATE(MID(X2,1,3)+1911,MID(X2,4,2),MID(X2,6,2)) -> 45009 | AG2: =1-(Y2-AD2)/Y2 -> 0.5641953
A3: =MAX(X:X) -> 1140204 | B3: =K6&J7 -> 33周前 | C3: 蘇柏亞 | D3: 女 | E3: =LOOKUP($A$3,日期,體重_kg) -> 55.4 | F3: =LOOKUP($A$3,日期,體重變化) -> -1.1 | G3: =IF(E3<C8,"Q1",IF(E3<C9,"Q2",IF(E3<C10,"Q3",IF(E3<3000,"Q4")))) -> Q2 | H3: =LOOKUP($A$3,日期,體脂率) -> 16.9 | I3: =LOOKUP($A$3,日期,體脂率變化) -> -0.5 | J3: =IF(H3<D8,"Q1",IF(H3<D9,"Q2",IF(H3<D10,"Q3",IF(H3<3000,"Q4")))) -> Q3 | K3: =LOOKUP($A$3,日期,脂肪重_kg) -> 9.4 | L3: =LOOKUP($A$3,日期,脂肪重變化) -> -0.4 | M3: =IF(K3<E8,"Q1",IF(K3<E9,"Q2",IF(K3<E10,"Q3",IF(K3<3000,"Q4")))) -> Q3 | N3: =LOOKUP($A$3,日期,去脂重_kg) -> 46 | O3: =LOOKUP($A$3,日期,去脂重變化) -> -0.7 | P3: =IF(N3<F8,"Q1",IF(N3<F9,"Q2",IF(N3<F10,"Q3",IF(N3<3000,"Q4")))) -> Q1 | Q3: =LOOKUP($A$3,日期,肌肉量) -> 43.1 | R3: =LOOKUP($A$3,日期,肌肉量變化) -> -0.7 | S3: =IF(Q3<G8,"Q1",IF(Q3<G9,"Q2",IF(Q3<G10,"Q3",IF(Q3<3000,"Q4")))) -> Q1 | T3: =LOOKUP($A$3,日期,身體總水份kg) -> 30.3 | U3: =LOOKUP($A$3,日期,水分變化KG) -> -0.8 | V3: =LOOKUP($A$3,日期,水分變化) -> -0.0035110699 | W3: =IF(T3<H8,"Q1",IF(T3<H9,"Q2",IF(T3<H10,"Q3",IF(T3<3000,"Q4")))) -> Q1 | X3: 1120413 | Y3: 55.8 | Z3: 14.2 | AA3: 7.9 | AB3: 47.9 | AC3: 44.9 | AD3: 32 | AE3: =X2 -> 1120324 | AF3: =DATE(MID(X3,1,3)+1911,MID(X3,4,2),MID(X3,6,2)) -> 45029 | AG3: =1-(Y3-AD3)/Y3 -> 0.5734767 | AH3: =Y3-Y2 -> 0.5 | AI3: =Z3-Z2 -> -1.3 | AJ3: =AA3-AA2 -> -0.7 | AK3: =AB3-AB2 -> 1.2 | AL3: =AC3-AC2 -> 1.1 | AM3: =AD3-AD2 -> 0.8 | AN3: =AG3-AG2 -> 0.0092814041
A4: =DATE(MID(A3,1,3)+1911,MID(A3,4,2),MID(A3,6,2)) -> 45692 | B4: =DATE(MID(B17,1,3)+1911,MID(B17,4,2),MID(B17,6,2)) -> 45463 | X4: 1120504 | Y4: 54.2 | Z4: 14.3 | AA4: 7.8 | AB4: 46.4 | AC4: 43.5 | AD4: 30.4 | AE4: =X3 -> 1120413 | AF4: =DATE(MID(X4,1,3)+1911,MID(X4,4,2),MID(X4,6,2)) -> 45050 | AG4: =1-(Y4-AD4)/Y4 -> 0.56088561 | AH4: =Y4-Y3 -> -1.6 | AI4: =Z4-Z3 -> 0.1 | AJ4: =AA4-AA3 -> -0.1 | AK4: =AB4-AB3 -> -1.5 | AL4: =AC4-AC3 -> -1.4 | AM4: =AD4-AD3 -> -1.6 | AN4: =AG4-AG3 -> -0.012591094
C5: 體重 | D5: 體脂率 | E5: 脂肪重 | F5: 去脂重 | G5: 肌肉重 | H5: 總水份 | X5: 1120629 | Y5: 54.4 | Z5: 14.1 | AA5: 7.7 | AB5: 46.7 | AC5: 43.8 | AD5: 30.5 | AE5: =X4 -> 1120504 | AF5: =DATE(MID(X5,1,3)+1911,MID(X5,4,2),MID(X5,6,2)) -> 45106 | AG5: =1-(Y5-AD5)/Y5 -> 0.56066176 | AH5: =Y5-Y4 -> 0.2 | AI5: =Z5-Z4 -> -0.2 | AJ5: =AA5-AA4 -> -0.1 | AK5: =AB5-AB4 -> 0.3 | AL5: =AC5-AC4 -> 0.3 | AM5: =AD5-AD4 -> 0.1 | AN5: =AG5-AG4 -> -0.00022384415
B6: Q1 | C6: =_xlfn.QUARTILE.INC(Y:Y,1) -> 52.425 | D6: =_xlfn.QUARTILE.INC(Z:Z,1) -> 12.95 | E6: =_xlfn.QUARTILE.INC(AA:AA,1) -> 6.75 | F6: =_xlfn.QUARTILE.INC(AB:AB,1) -> 45.65 | G6: =_xlfn.QUARTILE.INC(AC:AC,1) -> 42.85 | H6: =_xlfn.QUARTILE.INC(AD:AD,1) -> 29.9 | J6: =A4-B4 -> 229 | K6: =ROUND(K7,0) -> 33 | X6: 1120713 | Y6: 56.1 | Z6: 14.8 | AA6: 8.3 | AB6: 47.8 | AC6: 44.8 | AD6: 31.8 | AE6: =X5 -> 1120629 | AF6: =DATE(MID(X6,1,3)+1911,MID(X6,4,2),MID(X6,6,2)) -> 45120 | AG6: =1-(Y6-AD6)/Y6 -> 0.56684492 | AH6: =Y6-Y5 -> 1.7 | AI6: =Z6-Z5 -> 0.7 | AJ6: =AA6-AA5 -> 0.6 | AK6: =AB6-AB5 -> 1.1 | AL6: =AC6-AC5 -> 1 | AM6: =AD6-AD5 -> 1.3 | AN6: =AG6-AG5 -> 0.0061831551
B7: =C3 -> 蘇柏亞 | C7: =E3 -> 55.4 | D7: =H3 -> 16.9 | E7: =K3 -> 9.4 | F7: =N3 -> 46 | G7: =Q3 -> 43.1 | H7: =T3 -> 30.3 | J7: 周前 | K7: =J6/7 -> 32.714286 | X7: 1120720 | Y7: 55.6 | Z7: 16 | AA7: 8.9 | AB7: 46.7 | AC7: 43.8 | AD7: 30.7 | AE7: =X6 -> 1120713 | AF7: =DATE(MID(X7,1,3)+1911,MID(X7,4,2),MID(X7,6,2)) -> 45127 | AG7: =1-(Y7-AD7)/Y7 -> 0.55215827 | AH7: =Y7-Y6 -> -0.5 | AI7: =Z7-Z6 -> 1.2 | AJ7: =AA7-AA6 -> 0.6 | AK7: =AB7-AB6 -> -1.1 | AL7: =AC7-AC6 -> -1 | AM7: =AD7-AD6 -> -1.1 | AN7: =AG7-AG6 -> -0.014686646
A8: 低 | B8: Q2 | C8: =_xlfn.QUARTILE.INC(Y:Y,2) -> 55.1 | D8: =_xlfn.QUARTILE.INC(Z:Z,2) -> 14.7 | E8: =_xlfn.QUARTILE.INC(AA:AA,2) -> 8.1 | F8: =_xlfn.QUARTILE.INC(AB:AB,2) -> 46.35 | G8: =_xlfn.QUARTILE.INC(AC:AC,2) -> 43.45 | H8: =_xlfn.QUARTILE.INC(AD:AD,2) -> 30.45 | X8: 1120817 | Y8: 56.6 | Z8: 17 | AA8: 9.6 | AB8: 47 | AC8: 44.1 | AD8: 31.3 | AE8: =X7 -> 1120720 | AF8: =DATE(MID(X8,1,3)+1911,MID(X8,4,2),MID(X8,6,2)) -> 45155 | AG8: =1-(Y8-AD8)/Y8 -> 0.55300353 | AH8: =Y8-Y7 -> 1 | AI8: =Z8-Z7 -> 1 | AJ8: =AA8-AA7 -> 0.7 | AK8: =AB8-AB7 -> 0.3 | AL8: =AC8-AC7 -> 0.3 | AM8: =AD8-AD7 -> 0.6 | AN8: =AG8-AG7 -> 0.00084526019
A9: 中等 | B9: Q3 | C9: =_xlfn.QUARTILE.INC(Y:Y,3) -> 55.525 | D9: =_xlfn.QUARTILE.INC(Z:Z,3) -> 16 | E9: =_xlfn.QUARTILE.INC(AA:AA,3) -> 8.9 | F9: =_xlfn.QUARTILE.INC(AB:AB,3) -> 46.7 | G9: =_xlfn.QUARTILE.INC(AC:AC,3) -> 43.8 | H9: =_xlfn.QUARTILE.INC(AD:AD,3) -> 31.2 | X9: 1120824 | Y9: 56.8 | Z9: 15.4 | AA9: 8.7 | AB9: 48.1 | AC9: 45.1 | AD9: 32.3 | AE9: =X8 -> 1120817 | AF9: =DATE(MID(X9,1,3)+1911,MID(X9,4,2),MID(X9,6,2)) -> 45162 | AG9: =1-(Y9-AD9)/Y9 -> 0.56866197 | AH9: =Y9-Y8 -> 0.2 | AI9: =Z9-Z8 -> -1.6 | AJ9: =AA9-AA8 -> -0.9 | AK9: =AB9-AB8 -> 1.1 | AL9: =AC9-AC8 -> 1 | AM9: =AD9-AD8 -> 1 | AN9: =AG9-AG8 -> 0.015658438
A10: 高 | B10: Q4 | C10: =_xlfn.QUARTILE.INC(Y:Y,4) -> 56.8 | D10: =_xlfn.QUARTILE.INC(Z:Z,4) -> 17.4 | E10: =_xlfn.QUARTILE.INC(AA:AA,4) -> 9.8 | F10: =_xlfn.QUARTILE.INC(AB:AB,4) -> 48.1 | G10: =_xlfn.QUARTILE.INC(AC:AC,4) -> 45.1 | H10: =_xlfn.QUARTILE.INC(AD:AD,4) -> 32.3 | X10: 1120907 | Y10: 56.6 | Z10: 16.7 | AA10: 9.5 | AB10: 47.1 | AC10: 44.1 | AD10: 31.3 | AE10: =X9 -> 1120824 | AF10: =DATE(MID(X10,1,3)+1911,MID(X10,4,2),MID(X10,6,2)) -> 45176 | AG10: =1-(Y10-AD10)/Y10 -> 0.55300353 | AH10: =Y10-Y9 -> -0.2 | AI10: =Z10-Z9 -> 1.3 | AJ10: =AA10-AA9 -> 0.8 | AK10: =AB10-AB9 -> -1 | AL10: =AC10-AC9 -> -1 | AM10: =AD10-AD9 -> -1 | AN10: =AG10-AG9 -> -0.015658438
X11: 1121102 | Y11: 55.5 | Z11: 15.3 | AA11: 8.5 | AB11: 47 | AC11: 44.1 | AD11: 31.3 | AE11: =X10 -> 1120907 | AF11: =DATE(MID(X11,1,3)+1911,MID(X11,4,2),MID(X11,6,2)) -> 45232 | AG11: =1-(Y11-AD11)/Y11 -> 0.56396396 | AH11: =Y11-Y10 -> -1.1 | AI11: =Z11-Z10 -> -1.4 | AJ11: =AA11-AA10 -> -1 | AK11: =AB11-AB10 -> -0.1 | AL11: =AC11-AC10 -> 0 | AM11: =AD11-AD10 -> 0 | AN11: =AG11-AG10 -> 0.01096043
C12: 體重 | D12: 體脂率 | E12: 脂肪重 | F12: 去脂重 | G12: 肌肉重 | H12: 水份kg | I12: 水份% | X12: 1121116 | Y12: 55.1 | Z12: 16 | AA12: 8.8 | AB12: 46.3 | AC12: 43.4 | AD12: 30.3 | AE12: =X11 -> 1121102 | AF12: =DATE(MID(X12,1,3)+1911,MID(X12,4,2),MID(X12,6,2)) -> 45246 | AG12: =1-(Y12-AD12)/Y12 -> 0.54990926 | AH12: =Y12-Y11 -> -0.4 | AI12: =Z12-Z11 -> 0.7 | AJ12: =AA12-AA11 -> 0.3 | AK12: =AB12-AB11 -> -0.7 | AL12: =AC12-AC11 -> -0.7 | AM12: =AD12-AD11 -> -1 | AN12: =AG12-AG11 -> -0.014054708
B13: =LOOKUP(B14,日期,上次量測) -> 1130307 | C13: =LOOKUP(B13,日期,體重_kg) -> 50.6 | D13: =LOOKUP(B13,日期,體脂率) -> 12.8 | E13: =LOOKUP(B13,日期,脂肪重_kg) -> 6.5 | F13: =LOOKUP(B13,日期,去脂重_kg) -> 44.1 | G13: =LOOKUP(B13,日期,肌肉量) -> 41.4 | H13: =LOOKUP(B13,日期,身體總水份kg) -> 28.6 | I13: =LOOKUP(B13,日期,身體總水份) -> 0.56521739 | X13: 1121123 | Y13: 55.1 | Z13: 16.2 | AA13: 8.9 | AB13: 46.2 | AC13: 43.3 | AD13: 30.5 | AE13: =X12 -> 1121116 | AF13: =DATE(MID(X13,1,3)+1911,MID(X13,4,2),MID(X13,6,2)) -> 45253 | AG13: =1-(Y13-AD13)/Y13 -> 0.55353902 | AH13: =Y13-Y12 -> 0 | AI13: =Z13-Z12 -> 0.2 | AJ13: =AA13-AA12 -> 0.1 | AK13: =AB13-AB12 -> -0.1 | AL13: =AC13-AC12 -> -0.1 | AM13: =AD13-AD12 -> 0.2 | AN13: =AG13-AG12 -> 0.0036297641
B14: =LOOKUP(B15,日期,上次量測) -> 1130328 | C14: =LOOKUP(B14,日期,體重_kg) -> 55.1 | D14: =LOOKUP(B14,日期,體脂率) -> 15.6 | E14: =LOOKUP(B14,日期,脂肪重_kg) -> 8.6 | F14: =LOOKUP(B14,日期,去脂重_kg) -> 46.5 | G14: =LOOKUP(B14,日期,肌肉量) -> 43.6 | H14: =LOOKUP(B14,日期,身體總水份kg) -> 31.2 | I14: =LOOKUP(B14,日期,身體總水份) -> 0.56624319 | X14: 1121130 | Y14: 54.1 | Z14: 14.1 | AA14: 7.6 | AB14: 46.5 | AC14: 43.6 | AD14: 30.5 | AE14: =X13 -> 1121123 | AF14: =DATE(MID(X14,1,3)+1911,MID(X14,4,2),MID(X14,6,2)) -> 45260 | AG14: =1-(Y14-AD14)/Y14 -> 0.56377079 | AH14: =Y14-Y13 -> -1 | AI14: =Z14-Z13 -> -2.1 | AJ14: =AA14-AA13 -> -1.3 | AK14: =AB14-AB13 -> 0.3 | AL14: =AC14-AC13 -> 0.3 | AM14: =AD14-AD13 -> 0 | AN14: =AG14-AG13 -> 0.010231775
B15: =LOOKUP(B16,日期,上次量測) -> 1130502 | C15: =LOOKUP(B15,日期,體重_kg) -> 55.5 | D15: =LOOKUP(B15,日期,體脂率) -> 16 | E15: =LOOKUP(B15,日期,脂肪重_kg) -> 8.9 | F15: =LOOKUP(B15,日期,去脂重_kg) -> 46.6 | G15: =LOOKUP(B15,日期,肌肉量) -> 43.7 | H15: =LOOKUP(B15,日期,身體總水份kg) -> 31.1 | I15: =LOOKUP(B15,日期,身體總水份) -> 0.56036036 | X15: 1121207 | Y15: 53.7 | Z15: 14.6 | AA15: 7.8 | AB15: 45.9 | AC15: 43.1 | AD15: 30.1 | AE15: =X14 -> 1121130 | AF15: =DATE(MID(X15,1,3)+1911,MID(X15,4,2),MID(X15,6,2)) -> 45267 | AG15: =1-(Y15-AD15)/Y15 -> 0.56052142 | AH15: =Y15-Y14 -> -0.4 | AI15: =Z15-Z14 -> 0.5 | AJ15: =AA15-AA14 -> 0.2 | AK15: =AB15-AB14 -> -0.6 | AL15: =AC15-AC14 -> -0.5 | AM15: =AD15-AD14 -> -0.4 | AN15: =AG15-AG14 -> -0.0032493796
B16: =LOOKUP(B17,日期,上次量測) -> 1130509 | C16: =LOOKUP(B16,日期,體重_kg) -> 55.2 | D16: =LOOKUP(B16,日期,體脂率) -> 17.2 | E16: =LOOKUP(B16,日期,脂肪重_kg) -> 9.5 | F16: =LOOKUP(B16,日期,去脂重_kg) -> 45.7 | G16: =LOOKUP(B16,日期,肌肉量) -> 42.9 | H16: =LOOKUP(B16,日期,身體總水份kg) -> 30.1 | I16: =LOOKUP(B16,日期,身體總水份) -> 0.54528986 | X16: 1121214 | Y16: 53.4 | Z16: 13.8 | AA16: 7.4 | AB16: 46 | AC16: 43.1 | AD16: 30.3 | AE16: =X15 -> 1121207 | AF16: =DATE(MID(X16,1,3)+1911,MID(X16,4,2),MID(X16,6,2)) -> 45274 | AG16: =1-(Y16-AD16)/Y16 -> 0.56741573 | AH16: =Y16-Y15 -> -0.3 | AI16: =Z16-Z15 -> -0.8 | AJ16: =AA16-AA15 -> -0.4 | AK16: =AB16-AB15 -> 0.1 | AL16: =AC16-AC15 -> 0 | AM16: =AD16-AD15 -> 0.2 | AN16: =AG16-AG15 -> 0.0068943151
B17: =LOOKUP(B18,日期,上次量測) -> 1130620 | C17: =LOOKUP(B17,日期,體重_kg) -> 56.5 | D17: =LOOKUP(B17,日期,體脂率) -> 17.4 | E17: =LOOKUP(B17,日期,脂肪重_kg) -> 9.8 | F17: =LOOKUP(B17,日期,去脂重_kg) -> 46.7 | G17: =LOOKUP(B17,日期,肌肉量) -> 43.8 | H17: =LOOKUP(B17,日期,身體總水份kg) -> 31.1 | I17: =LOOKUP(B17,日期,身體總水份) -> 0.55044248 | X17: 1121221 | Y17: 52.6 | Z17: 13 | AA17: 6.8 | AB17: 45.8 | AC17: 43 | AD17: 30 | AE17: =X16 -> 1121214 | AF17: =DATE(MID(X17,1,3)+1911,MID(X17,4,2),MID(X17,6,2)) -> 45281 | AG17: =1-(Y17-AD17)/Y17 -> 0.57034221 | AH17: =Y17-Y16 -> -0.8 | AI17: =Z17-Z16 -> -0.8 | AJ17: =AA17-AA16 -> -0.6 | AK17: =AB17-AB16 -> -0.2 | AL17: =AC17-AC16 -> -0.1 | AM17: =AD17-AD16 -> -0.3 | AN17: =AG17-AG16 -> 0.002926475
B18: =A3 -> 1140204 | C18: =LOOKUP(B18,日期,體重_kg) -> 55.4 | D18: =LOOKUP(B18,日期,體脂率) -> 16.9 | E18: =LOOKUP(B18,日期,脂肪重_kg) -> 9.4 | F18: =LOOKUP(B18,日期,去脂重_kg) -> 46 | G18: =LOOKUP(B18,日期,肌肉量) -> 43.1 | H18: =LOOKUP(B18,日期,身體總水份kg) -> 30.3 | I18: =LOOKUP(B18,日期,身體總水份) -> 0.54693141 | X18: 1121228 | Y18: 51.9 | Z18: 12.3 | AA18: 6.4 | AB18: 45.5 | AC18: 42.7 | AD18: 29.6 | AE18: =X17 -> 1121221 | AF18: =DATE(MID(X18,1,3)+1911,MID(X18,4,2),MID(X18,6,2)) -> 45288 | AG18: =1-(Y18-AD18)/Y18 -> 0.57032755 | AH18: =Y18-Y17 -> -0.7 | AI18: =Z18-Z17 -> -0.7 | AJ18: =AA18-AA17 -> -0.4 | AK18: =AB18-AB17 -> -0.3 | AL18: =AC18-AC17 -> -0.3 | AM18: =AD18-AD17 -> -0.4 | AN18: =AG18-AG17 -> -1.4652337e-05
X19: 1130104 | Y19: 51.2 | Z19: 12.4 | AA19: 6.3 | AB19: 44.9 | AC19: 42.1 | AD19: 29.1 | AE19: =X18 -> 1121228 | AF19: =DATE(MID(X19,1,3)+1911,MID(X19,4,2),MID(X19,6,2)) -> 45295 | AG19: =1-(Y19-AD19)/Y19 -> 0.56835938 | AH19: =Y19-Y18 -> -0.7 | AI19: =Z19-Z18 -> 0.1 | AJ19: =AA19-AA18 -> -0.1 | AK19: =AB19-AB18 -> -0.6 | AL19: =AC19-AC18 -> -0.6 | AM19: =AD19-AD18 -> -0.5 | AN19: =AG19-AG18 -> -0.001968178
X20: 1130111 | Y20: 50.8 | Z20: 11.7 | AA20: 5.9 | AB20: 44.9 | AC20: 42.1 | AD20: 29.1 | AE20: =X19 -> 1130104 | AF20: =DATE(MID(X20,1,3)+1911,MID(X20,4,2),MID(X20,6,2)) -> 45302 | AG20: =1-(Y20-AD20)/Y20 -> 0.57283465 | AH20: =Y20-Y19 -> -0.4 | AI20: =Z20-Z19 -> -0.7 | AJ20: =AA20-AA19 -> -0.4 | AK20: =AB20-AB19 -> 0 | AL20: =AC20-AC19 -> 0 | AM20: =AD20-AD19 -> 0 | AN20: =AG20-AG19 -> 0.0044752707
X21: 1130118 | Y21: 50.6 | Z21: 12.8 | AA21: 6.5 | AB21: 44.1 | AC21: 41.4 | AD21: 28.6 | AE21: =X20 -> 1130111 | AF21: =DATE(MID(X21,1,3)+1911,MID(X21,4,2),MID(X21,6,2)) -> 45309 | AG21: =1-(Y21-AD21)/Y21 -> 0.56521739 | AH21: =Y21-Y20 -> -0.2 | AI21: =Z21-Z20 -> 1.1 | AJ21: =AA21-AA20 -> 0.6 | AK21: =AB21-AB20 -> -0.8 | AL21: =AC21-AC20 -> -0.7 | AM21: =AD21-AD20 -> -0.5 | AN21: =AG21-AG20 -> -0.0076172544
X22: 1130124 | Y22: 49 | Z22: 12.2 | AA22: 6 | AB22: 43 | AC22: 40.4 | AD22: 27.8 | AE22: =X21 -> 1130118 | AF22: =DATE(MID(X22,1,3)+1911,MID(X22,4,2),MID(X22,6,2)) -> 45315 | AG22: =1-(Y22-AD22)/Y22 -> 0.56734694 | AH22: =Y22-Y21 -> -1.6 | AI22: =Z22-Z21 -> -0.6 | AJ22: =AA22-AA21 -> -0.5 | AK22: =AB22-AB21 -> -1.1 | AL22: =AC22-AC21 -> -1 | AM22: =AD22-AD21 -> -0.8 | AN22: =AG22-AG21 -> 0.0021295475
X23: 1130229 | Y23: 51.4 | Z23: 12.8 | AA23: 6.6 | AB23: 44.8 | AC23: 42 | AD23: 29.2 | AE23: =X22 -> 1130124 | AF23: =DATE(MID(X23,1,3)+1911,MID(X23,4,2),MID(X23,6,2)) -> 45351 | AG23: =1-(Y23-AD23)/Y23 -> 0.56809339 | AH23: =Y23-Y22 -> 2.4 | AI23: =Z23-Z22 -> 0.6 | AJ23: =AA23-AA22 -> 0.6 | AK23: =AB23-AB22 -> 1.8 | AL23: =AC23-AC22 -> 1.6 | AM23: =AD23-AD22 -> 1.4 | AN23: =AG23-AG22 -> 0.00074644644
X24: 1130307 | Y24: 50.6 | Z24: 12.8 | AA24: 6.5 | AB24: 44.1 | AC24: 41.4 | AD24: 28.6 | AE24: =X23 -> 1130229 | AF24: =DATE(MID(X24,1,3)+1911,MID(X24,4,2),MID(X24,6,2)) -> 45358 | AG24: =1-(Y24-AD24)/Y24 -> 0.56521739 | AH24: =Y24-Y23 -> -0.8 | AI24: =Z24-Z23 -> 0 | AJ24: =AA24-AA23 -> -0.1 | AK24: =AB24-AB23 -> -0.7 | AL24: =AC24-AC23 -> -0.6 | AM24: =AD24-AD23 -> -0.6 | AN24: =AG24-AG23 -> -0.0028759939
X25: 1130328 | Y25: 55.1 | Z25: 15.6 | AA25: 8.6 | AB25: 46.5 | AC25: 43.6 | AD25: 31.2 | AE25: =X24 -> 1130307 | AF25: =DATE(MID(X25,1,3)+1911,MID(X25,4,2),MID(X25,6,2)) -> 45379 | AG25: =1-(Y25-AD25)/Y25 -> 0.56624319 | AH25: =Y25-Y24 -> 4.5 | AI25: =Z25-Z24 -> 2.8 | AJ25: =AA25-AA24 -> 2.1 | AK25: =AB25-AB24 -> 2.4 | AL25: =AC25-AC24 -> 2.2 | AM25: =AD25-AD24 -> 2.6 | AN25: =AG25-AG24 -> 0.0010258029
X26: 1130502 | Y26: 55.5 | Z26: 16 | AA26: 8.9 | AB26: 46.6 | AC26: 43.7 | AD26: 31.1 | AE26: =X25 -> 1130328 | AF26: =DATE(MID(X26,1,3)+1911,MID(X26,4,2),MID(X26,6,2)) -> 45414 | AG26: =1-(Y26-AD26)/Y26 -> 0.56036036 | AH26: =Y26-Y25 -> 0.4 | AI26: =Z26-Z25 -> 0.4 | AJ26: =AA26-AA25 -> 0.3 | AK26: =AB26-AB25 -> 0.1 | AL26: =AC26-AC25 -> 0.1 | AM26: =AD26-AD25 -> -0.1 | AN26: =AG26-AG25 -> -0.0058828338
X27: 1130509 | Y27: 55.2 | Z27: 17.2 | AA27: 9.5 | AB27: 45.7 | AC27: 42.9 | AD27: 30.1 | AE27: =X26 -> 1130502 | AF27: =DATE(MID(X27,1,3)+1911,MID(X27,4,2),MID(X27,6,2)) -> 45421 | AG27: =1-(Y27-AD27)/Y27 -> 0.54528986 | AH27: =Y27-Y26 -> -0.3 | AI27: =Z27-Z26 -> 1.2 | AJ27: =AA27-AA26 -> 0.6 | AK27: =AB27-AB26 -> -0.9 | AL27: =AC27-AC26 -> -0.8 | AM27: =AD27-AD26 -> -1 | AN27: =AG27-AG26 -> -0.015070505
X28: 1130620 | Y28: 56.5 | Z28: 17.4 | AA28: 9.8 | AB28: 46.7 | AC28: 43.8 | AD28: 31.1 | AE28: =X27 -> 1130509 | AF28: =DATE(MID(X28,1,3)+1911,MID(X28,4,2),MID(X28,6,2)) -> 45463 | AG28: =1-(Y28-AD28)/Y28 -> 0.55044248 | AH28: =Y28-Y27 -> 1.3 | AI28: =Z28-Z27 -> 0.2 | AJ28: =AA28-AA27 -> 0.3 | AK28: =AB28-AB27 -> 1 | AL28: =AC28-AC27 -> 0.9 | AM28: =AD28-AD27 -> 1 | AN28: =AG28-AG27 -> 0.0051526228
X29: 1140204 | Y29: 55.4 | Z29: 16.9 | AA29: 9.4 | AB29: 46 | AC29: 43.1 | AD29: 30.3 | AE29: =X28 -> 1130620 | AF29: =DATE(MID(X29,1,3)+1911,MID(X29,4,2),MID(X29,6,2)) -> 45692 | AG29: =1-(Y29-AD29)/Y29 -> 0.54693141 | AH29: =Y29-Y28 -> -1.1 | AI29: =Z29-Z28 -> -0.5 | AJ29: =AA29-AA28 -> -0.4 | AK29: =AB29-AB28 -> -0.7 | AL29: =AC29-AC28 -> -0.7 | AM29: =AD29-AD28 -> -0.8 | AN29: =AG29-AG28 -> -0.0035110699
AE30: =X29 -> 1140204 | AF30: =DATE(MID(X30,1,3)+1911,MID(X30,4,2),MID(X30,6,2)) -> #VALUE! | AG30: =1-(Y30-AD30)/Y30 -> #DIV/0! | AH30: =Y30-Y29 -> -55.4 | AI30: =Z30-Z29 -> -16.9 | AJ30: =AA30-AA29 -> -9.4 | AK30: =AB30-AB29 -> -46 | AL30: =AC30-AC29 -> -43.1 | AM30: =AD30-AD29 -> -30.3 | AN30: =AG30-AG29 -> #DIV/0!
AE31: =X30 -> 0 | AF31: =DATE(MID(X31,1,3)+1911,MID(X31,4,2),MID(X31,6,2)) -> #VALUE! | AG31: =1-(Y31-AD31)/Y31 -> #DIV/0! | AH31: =Y31-Y30 -> 0 | AI31: =Z31-Z30 -> 0 | AJ31: =AA31-AA30 -> 0 | AK31: =AB31-AB30 -> 0 | AL31: =AC31-AC30 -> 0 | AM31: =AD31-AD30 -> 0 | AN31: =AG31-AG30 -> #DIV/0!
AE32: =X31 -> 0 | AF32: =DATE(MID(X32,1,3)+1911,MID(X32,4,2),MID(X32,6,2)) -> #VALUE! | AG32: =1-(Y32-AD32)/Y32 -> #DIV/0! | AH32: =Y32-Y31 -> 0 | AI32: =Z32-Z31 -> 0 | AJ32: =AA32-AA31 -> 0 | AK32: =AB32-AB31 -> 0 | AL32: =AC32-AC31 -> 0 | AM32: =AD32-AD31 -> 0 | AN32: =AG32-AG31 -> #DIV/0!
AE33: =X32 -> 0 | AF33: =DATE(MID(X33,1,3)+1911,MID(X33,4,2),MID(X33,6,2)) -> #VALUE! | AG33: =1-(Y33-AD33)/Y33 -> #DIV/0! | AH33: =Y33-Y32 -> 0 | AI33: =Z33-Z32 -> 0 | AJ33: =AA33-AA32 -> 0 | AK33: =AB33-AB32 -> 0 | AL33: =AC33-AC32 -> 0 | AM33: =AD33-AD32 -> 0 | AN33: =AG33-AG32 -> #DIV/0!
AE34: =X33 -> 0 | AF34: =DATE(MID(X34,1,3)+1911,MID(X34,4,2),MID(X34,6,2)) -> #VALUE! | AG34: =1-(Y34-AD34)/Y34 -> #DIV/0! | AH34: =Y34-Y33 -> 0 | AI34: =Z34-Z33 -> 0 | AJ34: =AA34-AA33 -> 0 | AK34: =AB34-AB33 -> 0 | AL34: =AC34-AC33 -> 0 | AM34: =AD34-AD33 -> 0 | AN34: =AG34-AG33 -> #DIV/0!
AE35: =X34 -> 0 | AF35: =DATE(MID(X35,1,3)+1911,MID(X35,4,2),MID(X35,6,2)) -> #VALUE! | AG35: =1-(Y35-AD35)/Y35 -> #DIV/0! | AH35: =Y35-Y34 -> 0 | AI35: =Z35-Z34 -> 0 | AJ35: =AA35-AA34 -> 0 | AK35: =AB35-AB34 -> 0 | AL35: =AC35-AC34 -> 0 | AM35: =AD35-AD34 -> 0 | AN35: =AG35-AG34 -> #DIV/0!
AE36: =X35 -> 0 | AF36: =DATE(MID(X36,1,3)+1911,MID(X36,4,2),MID(X36,6,2)) -> #VALUE! | AG36: =1-(Y36-AD36)/Y36 -> #DIV/0! | AH36: =Y36-Y35 -> 0 | AI36: =Z36-Z35 -> 0 | AJ36: =AA36-AA35 -> 0 | AK36: =AB36-AB35 -> 0 | AL36: =AC36-AC35 -> 0 | AM36: =AD36-AD35 -> 0 | AN36: =AG36-AG35 -> #DIV/0!
AE37: =X36 -> 0 | AF37: =DATE(MID(X37,1,3)+1911,MID(X37,4,2),MID(X37,6,2)) -> #VALUE! | AG37: =1-(Y37-AD37)/Y37 -> #DIV/0! | AH37: =Y37-Y36 -> 0 | AI37: =Z37-Z36 -> 0 | AJ37: =AA37-AA36 -> 0 | AK37: =AB37-AB36 -> 0 | AL37: =AC37-AC36 -> 0 | AM37: =AD37-AD36 -> 0 | AN37: =AG37-AG36 -> #DIV/0!
AE38: =X37 -> 0 | AF38: =DATE(MID(X38,1,3)+1911,MID(X38,4,2),MID(X38,6,2)) -> #VALUE! | AG38: =1-(Y38-AD38)/Y38 -> #DIV/0! | AH38: =Y38-Y37 -> 0 | AI38: =Z38-Z37 -> 0 | AJ38: =AA38-AA37 -> 0 | AK38: =AB38-AB37 -> 0 | AL38: =AC38-AC37 -> 0 | AM38: =AD38-AD37 -> 0 | AN38: =AG38-AG37 -> #DIV/0!
AE39: =X38 -> 0 | AF39: =DATE(MID(X39,1,3)+1911,MID(X39,4,2),MID(X39,6,2)) -> #VALUE! | AG39: =1-(Y39-AD39)/Y39 -> #DIV/0! | AH39: =Y39-Y38 -> 0 | AI39: =Z39-Z38 -> 0 | AJ39: =AA39-AA38 -> 0 | AK39: =AB39-AB38 -> 0 | AL39: =AC39-AC38 -> 0 | AM39: =AD39-AD38 -> 0 | AN39: =AG39-AG38 -> #DIV/0!
AE40: =X39 -> 0 | AF40: =DATE(MID(X40,1,3)+1911,MID(X40,4,2),MID(X40,6,2)) -> #VALUE! | AG40: =1-(Y40-AD40)/Y40 -> #DIV/0! | AH40: =Y40-Y39 -> 0 | AI40: =Z40-Z39 -> 0 | AJ40: =AA40-AA39 -> 0 | AK40: =AB40-AB39 -> 0 | AL40: =AC40-AC39 -> 0 | AM40: =AD40-AD39 -> 0 | AN40: =AG40-AG39 -> #DIV/0!
...

Sheet 羅嘉翎
A1: 量測日期 | B1: 上次量測 | C1: 姓名 | D1: 性別 | E1: 體重 | H1: 體脂率 | K1: 脂肪重 | N1: 去脂肪重 | Q1: 肌肉重 | T1: 總水份 | X1: 日期 | Y1: 體重(kg) | Z1: 體脂率(%) | AA1: 脂肪重(kg) | AB1: 去脂重(kg) | AC1: 肌肉量 | AD1: 身體總水份kg | AE1: 上次量測 | AF1: 星期 | AG1: 身體總水份% | AH1: 體重變化 | AI1: 體脂率變化 | AJ1: 脂肪重變化 | AK1: 去脂重變化 | AL1: 肌肉量變化 | AM1: 水分變化KG | AN1: 水分變化%
A2: "選取" | E2: 體重 | F2: 變化 | G2: 區間 | H2: 體脂率 | I2: 變化 | J2: 區間 | K2: 脂肪重 | L2: 變化 | M2: 區間 | N2: 去脂重 | O2: 變化 | P2: 區間 | Q2: 肌肉重 | R2: 變化 | S2: 區間 | T2: 總水份 | U2: 變化 | V2: 變化% | W2: 區間 | X2: {=_xlfn._xlws.SORT(_xlfn._xlws.FILTER(資料輸入!F:L, ISNUMBER(MATCH(資料輸入!E:E, 羅嘉翎!C3, 0))), 1, TRUE)} -> 1120201 | Y2: 60.9 | Z2: 20 | AA2: 12.2 | AB2: 48.7 | AC2: 45.6 | AD2: 30.7 | AF2: =DATE(MID(X2,1,3)+1911,MID(X2,4,2),MID(X2,6,2)) -> 44958 | AG2: =1-(Y2-AD2)/Y2 -> 0.50410509
A3: =MAX(X:X) -> 1140102 | B3: =K6&J7 -> 1周前 | C3: 羅嘉翎 | D3: 女 | E3: =LOOKUP($A$3,日期,體重_kg) -> 62.2 | F3: =LOOKUP($A$3,日期,體重變化) -> -2.5 | G3: =IF(E3<C8,"Q1",IF(E3<C9,"Q2",IF(E3<C10,"Q3",IF(E3<3000,"Q4")))) -> Q2 | H3: =LOOKUP($A$3,日期,體脂率) -> 21.2 | I3: =LOOKUP($A$3,日期,體脂率變化) -> -3.3 | J3: =IF(H3<D8,"Q1",IF(H3<D9,"Q2",IF(H3<D10,"Q3",IF(H3<3000,"Q4")))) -> Q2 | K3: =LOOKUP($A$3,日期,脂肪重_kg) -> 13.2 | L3: =LOOKUP($A$3,日期,脂肪重變化) -> -2.7 | M3: =IF(K3<E8,"Q1",IF(K3<E9,"Q2",IF(K3<E10,"Q3",IF(K3<3000,"Q4")))) -> Q2 | N3: =LOOKUP($A$3,日期,去脂重_kg) -> 49 | O3: =LOOKUP($A$3,日期,去脂重變化) -> 0.2 | P3: =IF(N3<F8,"Q1",IF(N3<F9,"Q2",IF(N3<F10,"Q3",IF(N3<3000,"Q4")))) -> Q2 | Q3: =LOOKUP($A$3,日期,肌肉量) -> 45.9 | R3: =LOOKUP($A$3,日期,肌肉量變化) -> 0.2 | S3: =IF(Q3<G8,"Q1",IF(Q3<G9,"Q2",IF(Q3<G10,"Q3",IF(Q3<3000,"Q4")))) -> Q2 | T3: =LOOKUP($A$3,日期,身體總水份kg) -> 31.5 | U3: =LOOKUP($A$3,日期,水分變化KG) -> -0.3 | V3: =LOOKUP($A$3,日期,水分變化) -> 0.014931641 | W3: =IF(T3<H8,"Q1",IF(T3<H9,"Q2",IF(T3<H10,"Q3",IF(T3<3000,"Q4")))) -> Q2 | X3: 1120413 | Y3: 63.5 | Z3: 21.9 | AA3: 13.9 | AB3: 49.6 | AC3: 46.4 | AD3: 32.5 | AE3: =X2 -> 1120201 | AF3: =DATE(MID(X3,1,3)+1911,MID(X3,4,2),MID(X3,6,2)) -> 45029 | AG3: =1-(Y3-AD3)/Y3 -> 0.51181102 | AH3: =Y3-Y2 -> 2.6 | AI3: =Z3-Z2 -> 1.9 | AJ3: =AA3-AA2 -> 1.7 | AK3: =AB3-AB2 -> 0.9 | AL3: =AC3-AC2 -> 0.8 | AM3: =AD3-AD2 -> 1.8 | AN3: =AG3-AG2 -> 0.0077059333
A4: =DATE(MID(A3,1,3)+1911,MID(A3,4,2),MID(A3,6,2)) -> 45659 | B4: =DATE(MID(B17,1,3)+1911,MID(B17,4,2),MID(B17,6,2)) -> 45652 | X4: 1120504 | Y4: 61.1 | Z4: 21.3 | AA4: 13 | AB4: 48.1 | AC4: 45.1 | AD4: 30.5 | AE4: =X3 -> 1120413 | AF4: =DATE(MID(X4,1,3)+1911,MID(X4,4,2),MID(X4,6,2)) -> 45050 | AG4: =1-(Y4-AD4)/Y4 -> 0.49918167 | AH4: =Y4-Y3 -> -2.4 | AI4: =Z4-Z3 -> -0.6 | AJ4: =AA4-AA3 -> -0.9 | AK4: =AB4-AB3 -> -1.5 | AL4: =AC4-AC3 -> -1.3 | AM4: =AD4-AD3 -> -2 | AN4: =AG4-AG3 -> -0.012629354
C5: 體重 | D5: 體脂率 | E5: 脂肪重 | F5: 去脂重 | G5: 肌肉重 | H5: 總水份 | X5: 1120512 | Y5: 61.4 | Z5: 19.7 | AA5: 12.1 | AB5: 49.3 | AC5: 46.2 | AD5: 31.7 | AE5: =X4 -> 1120504 | AF5: =DATE(MID(X5,1,3)+1911,MID(X5,4,2),MID(X5,6,2)) -> 45058 | AG5: =1-(Y5-AD5)/Y5 -> 0.51628664 | AH5: =Y5-Y4 -> 0.3 | AI5: =Z5-Z4 -> -1.6 | AJ5: =AA5-AA4 -> -0.9 | AK5: =AB5-AB4 -> 1.2 | AL5: =AC5-AC4 -> 1.1 | AM5: =AD5-AD4 -> 1.2 | AN5: =AG5-AG4 -> 0.017104976
B6: Q1 | C6: =_xlfn.QUARTILE.INC(Y:Y,1) -> 60.875 | D6: =_xlfn.QUARTILE.INC(Z:Z,1) -> 20 | E6: =_xlfn.QUARTILE.INC(AA:AA,1) -> 12.175 | F6: =_xlfn.QUARTILE.INC(AB:AB,1) -> 48 | G6: =_xlfn.QUARTILE.INC(AC:AC,1) -> 45 | H6: =_xlfn.QUARTILE.INC(AD:AD,1) -> 30.775 | J6: =A4-B4 -> 7 | K6: =ROUND(K7,0) -> 1 | X6: 1120516 | Y6: 61.6 | Z6: 20.7 | AA6: 12.8 | AB6: 48.8 | AC6: 45.7 | AD6: 31.4 | AE6: =X5 -> 1120512 | AF6: =DATE(MID(X6,1,3)+1911,MID(X6,4,2),MID(X6,6,2)) -> 45062 | AG6: =1-(Y6-AD6)/Y6 -> 0.50974026 | AH6: =Y6-Y5 -> 0.2 | AI6: =Z6-Z5 -> 1 | AJ6: =AA6-AA5 -> 0.7 | AK6: =AB6-AB5 -> -0.5 | AL6: =AC6-AC5 -> -0.5 | AM6: =AD6-AD5 -> -0.3 | AN6: =AG6-AG5 -> -0.0065463852
B7: =C3 -> 羅嘉翎 | C7: =E3 -> 62.2 | D7: =H3 -> 21.2 | E7: =K3 -> 13.2 | F7: =N3 -> 49 | G7: =Q3 -> 45.9 | H7: =T3 -> 31.5 | J7: 周前 | K7: =J6/7 -> 1 | X7: 1120616 | Y7: 62.9 | Z7: 20.8 | AA7: 13.1 | AB7: 49.8 | AC7: 46.6 | AD7: 32.3 | AE7: =X6 -> 1120516 | AF7: =DATE(MID(X7,1,3)+1911,MID(X7,4,2),MID(X7,6,2)) -> 45093 | AG7: =1-(Y7-AD7)/Y7 -> 0.51351351 | AH7: =Y7-Y6 -> 1.3 | AI7: =Z7-Z6 -> 0.1 | AJ7: =AA7-AA6 -> 0.3 | AK7: =AB7-AB6 -> 1 | AL7: =AC7-AC6 -> 0.9 | AM7: =AD7-AD6 -> 0.9 | AN7: =AG7-AG6 -> 0.0037732538
A8: 低 | B8: Q2 | C8: =_xlfn.QUARTILE.INC(Y:Y,2) -> 61.6 | D8: =_xlfn.QUARTILE.INC(Z:Z,2) -> 21.05 | E8: =_xlfn.QUARTILE.INC(AA:AA,2) -> 13.1 | F8: =_xlfn.QUARTILE.INC(AB:AB,2) -> 48.8 | G8: =_xlfn.QUARTILE.INC(AC:AC,2) -> 45.7 | H8: =_xlfn.QUARTILE.INC(AD:AD,2) -> 31.45 | X8: 1120617 | Y8: 63 | Z8: 19.8 | AA8: 12.5 | AB8: 50.4 | AC8: 47 | AD8: 33 | AE8: =X7 -> 1120616 | AF8: =DATE(MID(X8,1,3)+1911,MID(X8,4,2),MID(X8,6,2)) -> 45094 | AG8: =1-(Y8-AD8)/Y8 -> 0.52380952 | AH8: =Y8-Y7 -> 0.1 | AI8: =Z8-Z7 -> -1 | AJ8: =AA8-AA7 -> -0.6 | AK8: =AB8-AB7 -> 0.6 | AL8: =AC8-AC7 -> 0.4 | AM8: =AD8-AD7 -> 0.7 | AN8: =AG8-AG7 -> 0.01029601
A9: 中等 | B9: Q3 | C9: =_xlfn.QUARTILE.INC(Y:Y,3) -> 63 | D9: =_xlfn.QUARTILE.INC(Z:Z,3) -> 22.425 | E9: =_xlfn.QUARTILE.INC(AA:AA,3) -> 13.95 | F9: =_xlfn.QUARTILE.INC(AB:AB,3) -> 49.3 | G9: =_xlfn.QUARTILE.INC(AC:AC,3) -> 46.2 | H9: =_xlfn.QUARTILE.INC(AD:AD,3) -> 31.9 | X9: 1120620 | Y9: 62.9 | Z9: 20.9 | AA9: 13.1 | AB9: 49.8 | AC9: 46.6 | AD9: 32 | AE9: =X8 -> 1120617 | AF9: =DATE(MID(X9,1,3)+1911,MID(X9,4,2),MID(X9,6,2)) -> 45097 | AG9: =1-(Y9-AD9)/Y9 -> 0.50874404 | AH9: =Y9-Y8 -> -0.1 | AI9: =Z9-Z8 -> 1.1 | AJ9: =AA9-AA8 -> 0.6 | AK9: =AB9-AB8 -> -0.6 | AL9: =AC9-AC8 -> -0.4 | AM9: =AD9-AD8 -> -1 | AN9: =AG9-AG8 -> -0.015065486
A10: 高 | B10: Q4 | C10: =_xlfn.QUARTILE.INC(Y:Y,4) -> 65.4 | D10: =_xlfn.QUARTILE.INC(Z:Z,4) -> 25.9 | E10: =_xlfn.QUARTILE.INC(AA:AA,4) -> 16.9 | F10: =_xlfn.QUARTILE.INC(AB:AB,4) -> 50.4 | G10: =_xlfn.QUARTILE.INC(AC:AC,4) -> 47 | H10: =_xlfn.QUARTILE.INC(AD:AD,4) -> 33 | X10: 1120626 | Y10: 62.9 | Z10: 21.3 | AA10: 13.4 | AB10: 49.5 | AC10: 46.3 | AD10: 32.3 | AE10: =X9 -> 1120620 | AF10: =DATE(MID(X10,1,3)+1911,MID(X10,4,2),MID(X10,6,2)) -> 45103 | AG10: =1-(Y10-AD10)/Y10 -> 0.51351351 | AH10: =Y10-Y9 -> 0 | AI10: =Z10-Z9 -> 0.4 | AJ10: =AA10-AA9 -> 0.3 | AK10: =AB10-AB9 -> -0.3 | AL10: =AC10-AC9 -> -0.3 | AM10: =AD10-AD9 -> 0.3 | AN10: =AG10-AG9 -> 0.0047694754
X11: 1120629 | Y11: 63 | Z11: 20.9 | AA11: 13.2 | AB11: 49.8 | AC11: 46.6 | AD11: 32.4 | AE11: =X10 -> 1120626 | AF11: =DATE(MID(X11,1,3)+1911,MID(X11,4,2),MID(X11,6,2)) -> 45106 | AG11: =1-(Y11-AD11)/Y11 -> 0.51428571 | AH11: =Y11-Y10 -> 0.1 | AI11: =Z11-Z10 -> -0.4 | AJ11: =AA11-AA10 -> -0.2 | AK11: =AB11-AB10 -> 0.3 | AL11: =AC11-AC10 -> 0.3 | AM11: =AD11-AD10 -> 0.1 | AN11: =AG11-AG10 -> 0.00077220077
C12: 體重 | D12: 體脂率 | E12: 脂肪重 | F12: 去脂重 | G12: 肌肉重 | H12: 水份kg | I12: 水份% | X12: 1120717 | Y12: 62 | Z12: 20.9 | AA12: 13 | AB12: 49 | AC12: 45.9 | AD12: 31.8 | AE12: =X11 -> 1120629 | AF12: =DATE(MID(X12,1,3)+1911,MID(X12,4,2),MID(X12,6,2)) -> 45124 | AG12: =1-(Y12-AD12)/Y12 -> 0.51290323 | AH12: =Y12-Y11 -> -1 | AI12: =Z12-Z11 -> 0 | AJ12: =AA12-AA11 -> -0.2 | AK12: =AB12-AB11 -> -0.8 | AL12: =AC12-AC11 -> -0.7 | AM12: =AD12-AD11 -> -0.6 | AN12: =AG12-AG11 -> -0.0013824885
B13: =LOOKUP(B14,日期,上次量測) -> 1130712 | C13: =LOOKUP(B13,日期,體重_kg) -> 60.8 | D13: =LOOKUP(B13,日期,體脂率) -> 21.6 | E13: =LOOKUP(B13,日期,脂肪重_kg) -> 13.1 | F13: =LOOKUP(B13,日期,去脂重_kg) -> 47.7 | G13: =LOOKUP(B13,日期,肌肉量) -> 44.7 | H13: =LOOKUP(B13,日期,身體總水份kg) -> 30.7 | I13: =LOOKUP(B13,日期,身體總水份) -> 0.50493421 | X13: 1120719 | Y13: 61.1 | Z13: 19.7 | AA13: 12 | AB13: 49.1 | AC13: 46 | AD13: 31.5 | AE13: =X12 -> 1120717 | AF13: =DATE(MID(X13,1,3)+1911,MID(X13,4,2),MID(X13,6,2)) -> 45126 | AG13: =1-(Y13-AD13)/Y13 -> 0.51554828 | AH13: =Y13-Y12 -> -0.9 | AI13: =Z13-Z12 -> -1.2 | AJ13: =AA13-AA12 -> -1 | AK13: =AB13-AB12 -> 0.1 | AL13: =AC13-AC12 -> 0.1 | AM13: =AD13-AD12 -> -0.3 | AN13: =AG13-AG12 -> 0.0026450557
B14: =LOOKUP(B15,日期,上次量測) -> 1130719 | C14: =LOOKUP(B14,日期,體重_kg) -> 61 | D14: =LOOKUP(B14,日期,體脂率) -> 22.4 | E14: =LOOKUP(B14,日期,脂肪重_kg) -> 13.7 | F14: =LOOKUP(B14,日期,去脂重_kg) -> 47.3 | G14: =LOOKUP(B14,日期,肌肉量) -> 44.3 | H14: =LOOKUP(B14,日期,身體總水份kg) -> 30.5 | I14: =LOOKUP(B14,日期,身體總水份) -> 0.5 | X14: 1120720 | Y14: 60.3 | Z14: 19.7 | AA14: 11.9 | AB14: 48.4 | AC14: 45.3 | AD14: 30.9 | AE14: =X13 -> 1120719 | AF14: =DATE(MID(X14,1,3)+1911,MID(X14,4,2),MID(X14,6,2)) -> 45127 | AG14: =1-(Y14-AD14)/Y14 -> 0.51243781 | AH14: =Y14-Y13 -> -0.8 | AI14: =Z14-Z13 -> 0 | AJ14: =AA14-AA13 -> -0.1 | AK14: =AB14-AB13 -> -0.7 | AL14: =AC14-AC13 -> -0.7 | AM14: =AD14-AD13 -> -0.6 | AN14: =AG14-AG13 -> -0.0031104706
B15: =LOOKUP(B16,日期,上次量測) -> 1130730 | C15: =LOOKUP(B15,日期,體重_kg) -> 59.2 | D15: =LOOKUP(B15,日期,體脂率) -> 21.9 | E15: =LOOKUP(B15,日期,脂肪重_kg) -> 13 | F15: =LOOKUP(B15,日期,去脂重_kg) -> 46.2 | G15: =LOOKUP(B15,日期,肌肉量) -> 43.3 | H15: =LOOKUP(B15,日期,身體總水份kg) -> 29.5 | I15: =LOOKUP(B15,日期,身體總水份) -> 0.49831081 | X15: 1120724 | Y15: 60.7 | Z15: 18.8 | AA15: 11.4 | AB15: 49.3 | AC15: 46.2 | AD15: 31.6 | AE15: =X14 -> 1120720 | AF15: =DATE(MID(X15,1,3)+1911,MID(X15,4,2),MID(X15,6,2)) -> 45131 | AG15: =1-(Y15-AD15)/Y15 -> 0.52059308 | AH15: =Y15-Y14 -> 0.4 | AI15: =Z15-Z14 -> -0.9 | AJ15: =AA15-AA14 -> -0.5 | AK15: =AB15-AB14 -> 0.9 | AL15: =AC15-AC14 -> 0.9 | AM15: =AD15-AD14 -> 0.7 | AN15: =AG15-AG14 -> 0.0081552698
B16: =LOOKUP(B17,日期,上次量測) -> 1131219 | C16: =LOOKUP(B16,日期,體重_kg) -> 65.4 | D16: =LOOKUP(B16,日期,體脂率) -> 25.9 | E16: =LOOKUP(B16,日期,脂肪重_kg) -> 16.9 | F16: =LOOKUP(B16,日期,去脂重_kg) -> 48.5 | G16: =LOOKUP(B16,日期,肌肉量) -> 45.4 | H16: =LOOKUP(B16,日期,身體總水份kg) -> 31.7 | I16: =LOOKUP(B16,日期,身體總水份) -> 0.48470948 | X16: 1120726 | Y16: 60 | Z16: 20.2 | AA16: 12.1 | AB16: 47.9 | AC16: 44.9 | AD16: 30.7 | AE16: =X15 -> 1120724 | AF16: =DATE(MID(X16,1,3)+1911,MID(X16,4,2),MID(X16,6,2)) -> 45133 | AG16: =1-(Y16-AD16)/Y16 -> 0.51166667 | AH16: =Y16-Y15 -> -0.7 | AI16: =Z16-Z15 -> 1.4 | AJ16: =AA16-AA15 -> 0.7 | AK16: =AB16-AB15 -> -1.4 | AL16: =AC16-AC15 -> -1.3 | AM16: =AD16-AD15 -> -0.9 | AN16: =AG16-AG15 -> -0.0089264141
B17: =LOOKUP(B18,日期,上次量測) -> 1131226 | C17: =LOOKUP(B17,日期,體重_kg) -> 64.7 | D17: =LOOKUP(B17,日期,體脂率) -> 24.5 | E17: =LOOKUP(B17,日期,脂肪重_kg) -> 15.9 | F17: =LOOKUP(B17,日期,去脂重_kg) -> 48.8 | G17: =LOOKUP(B17,日期,肌肉量) -> 45.7 | H17: =LOOKUP(B17,日期,身體總水份kg) -> 31.8 | I17: =LOOKUP(B17,日期,身體總水份) -> 0.49149923 | X17: 1120811 | Y17: 62.4 | Z17: 21.7 | AA17: 13.5 | AB17: 48.9 | AC17: 45.8 | AD17: 31.9 | AE17: =X16 -> 1120726 | AF17: =DATE(MID(X17,1,3)+1911,MID(X17,4,2),MID(X17,6,2)) -> 45149 | AG17: =1-(Y17-AD17)/Y17 -> 0.51121795 | AH17: =Y17-Y16 -> 2.4 | AI17: =Z17-Z16 -> 1.5 | AJ17: =AA17-AA16 -> 1.4 | AK17: =AB17-AB16 -> 1 | AL17: =AC17-AC16 -> 0.9 | AM17: =AD17-AD16 -> 1.2 | AN17: =AG17-AG16 -> -0.00044871795
B18: =A3 -> 1140102 | C18: =LOOKUP(B18,日期,體重_kg) -> 62.2 | D18: =LOOKUP(B18,日期,體脂率) -> 21.2 | E18: =LOOKUP(B18,日期,脂肪重_kg) -> 13.2 | F18: =LOOKUP(B18,日期,去脂重_kg) -> 49 | G18: =LOOKUP(B18,日期,肌肉量) -> 45.9 | H18: =LOOKUP(B18,日期,身體總水份kg) -> 31.5 | I18: =LOOKUP(B18,日期,身體總水份) -> 0.50643087 | X18: 1120814 | Y18: 61.8 | Z18: 20.7 | AA18: 12.8 | AB18: 49 | AC18: 45.9 | AD18: 31.4 | AE18: =X17 -> 1120811 | AF18: =DATE(MID(X18,1,3)+1911,MID(X18,4,2),MID(X18,6,2)) -> 45152 | AG18: =1-(Y18-AD18)/Y18 -> 0.50809061 | AH18: =Y18-Y17 -> -0.6 | AI18: =Z18-Z17 -> -1 | AJ18: =AA18-AA17 -> -0.7 | AK18: =AB18-AB17 -> 0.1 | AL18: =AC18-AC17 -> 0.1 | AM18: =AD18-AD17 -> -0.5 | AN18: =AG18-AG17 -> -0.0031273338
X19: 1120817 | Y19: 61.6 | Z19: 20.1 | AA19: 12.4 | AB19: 49.2 | AC19: 46.1 | AD19: 31.3 | AE19: =X18 -> 1120814 | AF19: =DATE(MID(X19,1,3)+1911,MID(X19,4,2),MID(X19,6,2)) -> 45155 | AG19: =1-(Y19-AD19)/Y19 -> 0.50811688 | AH19: =Y19-Y18 -> -0.2 | AI19: =Z19-Z18 -> -0.6 | AJ19: =AA19-AA18 -> -0.4 | AK19: =AB19-AB18 -> 0.2 | AL19: =AC19-AC18 -> 0.2 | AM19: =AD19-AD18 -> -0.1 | AN19: =AG19-AG18 -> 2.626823e-05
X20: 1120822 | Y20: 60.6 | Z20: 20 | AA20: 12.1 | AB20: 48.5 | AC20: 45.4 | AD20: 31.2 | AE20: =X19 -> 1120817 | AF20: =DATE(MID(X20,1,3)+1911,MID(X20,4,2),MID(X20,6,2)) -> 45160 | AG20: =1-(Y20-AD20)/Y20 -> 0.51485149 | AH20: =Y20-Y19 -> -1 | AI20: =Z20-Z19 -> -0.1 | AJ20: =AA20-AA19 -> -0.3 | AK20: =AB20-AB19 -> -0.7 | AL20: =AC20-AC19 -> -0.7 | AM20: =AD20-AD19 -> -0.1 | AN20: =AG20-AG19 -> 0.006734602
X21: 1120911 | Y21: 61.2 | Z21: 19.2 | AA21: 11.8 | AB21: 49.4 | AC21: 46.2 | AD21: 31.9 | AE21: =X20 -> 1120822 | AF21: =DATE(MID(X21,1,3)+1911,MID(X21,4,2),MID(X21,6,2)) -> 45180 | AG21: =1-(Y21-AD21)/Y21 -> 0.52124183 | AH21: =Y21-Y20 -> 0.6 | AI21: =Z21-Z20 -> -0.8 | AJ21: =AA21-AA20 -> -0.3 | AK21: =AB21-AB20 -> 0.9 | AL21: =AC21-AC20 -> 0.8 | AM21: =AD21-AD20 -> 0.7 | AN21: =AG21-AG20 -> 0.0063903449
X22: 1120913 | Y22: 60.1 | Z22: 19.9 | AA22: 12 | AB22: 48.1 | AC22: 45.1 | AD22: 30.8 | AE22: =X21 -> 1120911 | AF22: =DATE(MID(X22,1,3)+1911,MID(X22,4,2),MID(X22,6,2)) -> 45182 | AG22: =1-(Y22-AD22)/Y22 -> 0.5124792 | AH22: =Y22-Y21 -> -1.1 | AI22: =Z22-Z21 -> 0.7 | AJ22: =AA22-AA21 -> 0.2 | AK22: =AB22-AB21 -> -1.3 | AL22: =AC22-AC21 -> -1.1 | AM22: =AD22-AD21 -> -1.1 | AN22: =AG22-AG21 -> -0.0087626287
